Workbook
Name LegacyFiles: 'DropdownData'!$A$2:$A$11
Name AUTH_SIGNATORY: 'DropdownData'!$B$2:$B$17
Name CPV_DETAIL: 'DropdownData'!$C$2:$C$105
Name CUSTOMER_BANK: 'DropdownData'!$D$2:$D$13
Name GURANTOR: 'DropdownData'!$E$2:$E$34
Name RC_CUSTOMER_ACCOUNT: 'DropdownData'!$F$2:$F$161
Name RC_DOC_DESPATCH_MASTER: 'DropdownData'!$G$2:$G$10
Name RC_INSTRUMENT_DETAIL: 'DropdownData'!$H$2:$H$21
Name RC_RC_INV_RECEIVING_DETAIL: 'DropdownData'!$I$2:$I$23
Name RC_RC_INV_STATUS: 'DropdownData'!$J$2:$J$28
Name RC_SOURCE_REFERENCE: 'DropdownData'!$K$2:$K$6

Sheet MappingEditor
A1: new_field | B1: new_page | C1: new_section | D1: applies_when | E1: flow_notes | F1: legacy_file | G1: legacy_field | H1: fallback_priority | I1: transform | J1: active | K1: notes | L1: example_legacy_value | M1: example_new_value | N1: case_value_preview
A2: typeOfLoan | B2: Profile | C2: Loan Form With Steps | D2: Always (drives downstream flow) | E2: Core flow selector: New Car / Used Car / Car Cash-in / Refinance. | F2: RC_CUSTOMER_ACCOUNT.json | G2: CASE_TYPE | H2: 1 | I2: identity | J2: Y | K2: **Priority is `CASE_TYPE`**; map contains `cash-in` => `Car Cash-in`, `refinance` => `Refinance`, `used` => `Used Car`, else `New Car`. | N2: =IFERROR(XLOOKUP($F2&"."&$G2,CaseSource!$A$2:$A$371,CaseSource!$B$2:$B$371,""),"")
A3: typeOfLoan | B3: Profile | C3: Loan Form With Steps | D3: Always (drives downstream flow) | E3: Core flow selector: New Car / Used Car / Car Cash-in / Refinance. | F3: CPV_DETAIL.json | G3: TYPE_OF_LOAN | H3: 2 | I3: identity | J3: Y | K3: **Priority is `CASE_TYPE`**; map contains `cash-in` => `Car Cash-in`, `refinance` => `Refinance`, `used` => `Used Car`, else `New Car`. | N3: =IFERROR(XLOOKUP($F3&"."&$G3,CaseSource!$A$2:$A$371,CaseSource!$B$2:$B$371,""),"")
A4: typeOfLoan | B4: Profile | C4: Loan Form With Steps | D4: Always (drives downstream flow) | E4: Core flow selector: New Car / Used Car / Car Cash-in / Refinance. | F4: CPV_DETAIL.json | G4: LOAN_TYPE | H4: 3 | I4: identity | J4: Y | K4: **Priority is `CASE_TYPE`**; map contains `cash-in` => `Car Cash-in`, `refinance` => `Refinance`, `used` => `Used Car`, else `New Car`. | N4: =IFERROR(XLOOKUP($F4&"."&$G4,CaseSource!$A$2:$A$371,CaseSource!$B$2:$B$371,""),"")
A5: typeOfLoan | B5: Profile | C5: Loan Form With Steps | D5: Always (drives downstream flow) | E5: Core flow selector: New Car / Used Car / Car Cash-in / Refinance. | F5: CPV_DETAIL.json | G5: HIRE_PURPOSE | H5: 4 | I5: identity | J5: Y | K5: **Priority is `CASE_TYPE`**; map contains `cash-in` => `Car Cash-in`, `refinance` => `Refinance`, `used` => `Used Car`, else `New Car`. | N5: =IFERROR(XLOOKUP($F5&"."&$G5,CaseSource!$A$2:$A$371,CaseSource!$B$2:$B$371,""),"")
A6: typeOfLoan | B6: Profile | C6: Loan Form With Steps | D6: Always (drives downstream flow) | E6: Core flow selector: New Car / Used Car / Car Cash-in / Refinance. | F6: CPV_DETAIL.json | G6: PURPOSE_OF_LOAN | H6: 5 | I6: identity | J6: Y | K6: **Priority is `CASE_TYPE`**; map contains `cash-in` => `Car Cash-in`, `refinance` => `Refinance`, `used` => `Used Car`, else `New Car`. | N6: =IFERROR(XLOOKUP($F6&"."&$G6,CaseSource!$A$2:$A$371,CaseSource!$B$2:$B$371,""),"")
A7: typeOfLoan | B7: Profile | C7: Loan Form With Steps | D7: Always (drives downstream flow) | E7: Core flow selector: New Car / Used Car / Car Cash-in / Refinance. | F7: RC_CUSTOMER_ACCOUNT.json | G7: TYPE_OF_LOAN | H7: 6 | I7: identity | J7: Y | K7: **Priority is `CASE_TYPE`**; map contains `cash-in` => `Car Cash-in`, `refinance` => `Refinance`, `used` => `Used Car`, else `New Car`. | N7: =IFERROR(XLOOKUP($F7&"."&$G7,CaseSource!$A$2:$A$371,CaseSource!$B$2:$B$371,""),"")
A8: typeOfLoan | B8: Profile | C8: Loan Form With Steps | D8: Always (drives downstream flow) | E8: Core flow selector: New Car / Used Car / Car Cash-in / Refinance. | F8: RC_CUSTOMER_ACCOUNT.json | G8: LOAN_TYPE | H8: 7 | I8: identity | J8: Y | K8: **Priority is `CASE_TYPE`**; map contains `cash-in` => `Car Cash-in`, `refinance` => `Refinance`, `used` => `Used Car`, else `New Car`. | N8: =IFERROR(XLOOKUP($F8&"."&$G8,CaseSource!$A$2:$A$371,CaseSource!$B$2:$B$371,""),"")
A9: typeOfLoan | B9: Profile | C9: Loan Form With Steps | D9: Always (drives downstream flow) | E9: Core flow selector: New Car / Used Car / Car Cash-in / Refinance. | F9: RC_CUSTOMER_ACCOUNT.json | G9: LOAN_FOR | H9: 8 | I9: identity | J9: Y | K9: **Priority is `CASE_TYPE`**; map contains `cash-in` => `Car Cash-in`, `refinance` => `Refinance`, `used` => `Used Car`, else `New Car`. | N9: =IFERROR(XLOOKUP($F9&"."&$G9,CaseSource!$A$2:$A$371,CaseSource!$B$2:$B$371,""),"")
A10: isFinanced | B10: Profile | C10: Loan Form With Steps | D10: Always | E10: If No => cash flow (Profile + Delivery only). If Yes => Pre-File/Approval/Post-File/Delivery/Payout flow. | F10: RC_CUSTOMER_ACCOUNT.json | G10: LOAN_AMOUNT | H10: 1 | I10: identity | J10: Y | K10: `Car Cash-in/Refinance => Yes`; else loan amount or financier present => `Yes`, else `No`. | N10: =IFERROR(XLOOKUP($F10&"."&$G10,CaseSource!$A$2:$A$371,CaseSource!$B$2:$B$371,""),"")
A11: isFinanced | B11: Profile | C11: Loan Form With Steps | D11: Always | E11: If No => cash flow (Profile + Delivery only). If Yes => Pre-File/Approval/Post-File/Delivery/Payout flow. | F11: RC_CUSTOMER_ACCOUNT.json | G11: APPLIED_LOAN_AMOUNT | H11: 2 | I11: identity | J11: Y | K11: `Car Cash-in/Refinance => Yes`; else loan amount or financier present => `Yes`, else `No`. | N11: =IFERROR(XLOOKUP($F11&"."&$G11,CaseSource!$A$2:$A$371,CaseSource!$B$2:$B$371,""),"")
A12: isFinanced | B12: Profile | C12: Loan Form With Steps | D12: Always | E12: If No => cash flow (Profile + Delivery only). If Yes => Pre-File/Approval/Post-File/Delivery/Payout flow. | F12: CPV_DETAIL.json | G12: LOAN_EXPECTED | H12: 3 | I12: identity | J12: Y | K12: `Car Cash-in/Refinance => Yes`; else loan amount or financier present => `Yes`, else `No`. | N12: =IFERROR(XLOOKUP($F12&"."&$G12,CaseSource!$A$2:$A$371,CaseSource!$B$2:$B$371,""),"")
A13: isFinanced | B13: Profile | C13: Loan Form With Steps | D13: Always | E13: If No => cash flow (Profile + Delivery only). If Yes => Pre-File/Approval/Post-File/Delivery/Payout flow. | F13: RC_CUSTOMER_ACCOUNT.json | G13: HP_TO | H13: 4 | I13: identity | J13: Y | K13: `Car Cash-in/Refinance => Yes`; else loan amount or financier present => `Yes`, else `No`. | N13: =IFERROR(XLOOKUP($F13&"."&$G13,CaseSource!$A$2:$A$371,CaseSource!$B$2:$B$371,""),"")
... A20: currentStage | B20: Shared | C20: Loan Form With Steps | D20: Always | E20: Must respect legacy approval/disbursement progression for migration cases. | F20: RC_CUSTOMER_ACCOUNT.json | G20: DATE_WHEN_FILE_DESPATCH | H20: 6 | I20: identity | J20: Y | K20: If cash loan (`isFinanced=No`) => `delivery`; cash-in/refinance with disburse => `payout`; else delivery/disburse/dispatch fallback. | N20: =IFERROR(XLOOKUP($F20&"."&$G20,CaseSource!$A$2:$A$371,CaseSource!$B$2:$B$371,""),"")
A21: customerName | B21: Profile | C21: Emicustomer Details | D21: Always | F21: RC_CUSTOMER_ACCOUNT.json | G21: CUST_NAME | H21: 1 | I21: identity | J21: Y | K21: `pickName(...)` uses case-aware row preference. | N21: =IFERROR(XLOOKUP($F21&"."&$G21,CaseSource!$A$2:$A$371,CaseSource!$B$2:$B$371,""),"")
A22: customerName | B22: Profile | C22: Emicustomer Details | D22: Always | F22: CPV_DETAIL.json | G22: CUSTOMER_NAME | H22: 2 | I22: identity | J22: Y | K22: `pickName(...)` uses case-aware row preference. | N22: =IFERROR(XLOOKUP($F22&"."&$G22,CaseSource!$A$2:$A$371,CaseSource!$B$2:$B$371,""),"")
A23: applicantType | B23: Profile | C23: Lead Details | D23: Always | E23: Individual vs Company changes form visibility and required sections. | F23: CPV_DETAIL.json | G23: HIRE_TYPE | H23: 1 | I23: identity | J23: Y | K23: `normalizeApplicantType(...)` => `Individual`/`Company`. | N23: =IFERROR(XLOOKUP($F23&"."&$G23,CaseSource!$A$2:$A$371,CaseSource!$B$2:$B$371,""),"")
A24: primaryMobile | B24: Profile | C24: Emicustomer Details | D24: Always | F24: CPV_DETAIL.json | G24: OFF_PHONE1 | H24: 1 | I24: identity | J24: Y | K24: Clean numeric text. | N24: =IFERROR(XLOOKUP($F24&"."&$G24,CaseSource!$A$2:$A$371,CaseSource!$B$2:$B$371,""),"")
A25: primaryMobile | B25: Profile | C25: Emicustomer Details | D25: Always | F25: GURANTOR.json | G25: OFF_PHONE | H25: 2 | I25: identity | J25: Y | K25: Clean numeric text. | N25: =IFERROR(XLOOKUP($F25&"."&$G25,CaseSource!$A$2:$A$371,CaseSource!$B$2:$B$371,""),"")
A26: primaryMobile | B26: Profile | C26: Emicustomer Details | D26: Always | F26: RC_CUSTOMER_ACCOUNT.json | G26: PHONE_NUMBERS_OFFICE | H26: 3 | I26: identity | J26: Y | K26: Clean numeric text. | N26: =IFERROR(XLOOKUP($F26&"."&$G26,CaseSource!$A$2:$A$371,CaseSource!$B$2:$B$371,""),"")
A27: primaryMobile | B27: Profile | C27: Emicustomer Details | D27: Always | F27: AUTH_SIGNATORY.json | G27: PHONE | H27: 4 | I27: identity | J27: Y | K27: Clean numeric text. | N27: =IFERROR(XLOOKUP($F27&"."&$G27,CaseSource!$A$2:$A$371,CaseSource!$B$2:$B$371,""),"")
A28: primaryMobile | B28: Profile | C28: Emicustomer Details | D28: Always | F28: CPV_DETAIL.json | G28: RESI_PHONE1 | H28: 5 | I28: identity | J28: Y | K28: Clean numeric text. | N28: =IFERROR(XLOOKUP($F28&"."&$G28,CaseSource!$A$2:$A$371,CaseSource!$B$2:$B$371,""),"")
A29: primaryMobile | B29: Profile | C29: Emicustomer Details | D29: Always | F29: CPV_DETAIL.json | G29: MOBILE | H29: 6 | I29: identity | J29: Y | K29: Clean numeric text. | N29: =IFERROR(XLOOKUP($F29&"."&$G29,CaseSource!$A$2:$A$371,CaseSource!$B$2:$B$371,""),"")
A30: primaryMobile | B30: Profile | C30: Emicustomer Details | D30: Always | F30: RC_CUSTOMER_ACCOUNT.json | G30: MOBILE_NUMBER | H30: 7 | I30: identity | J30: Y | K30: Clean numeric text. | N30: =IFERROR(XLOOKUP($F30&"."&$G30,CaseSource!$A$2:$A$371,CaseSource!$B$2:$B$371,""),"")
A31: primaryMobile | B31: Profile | C31: Emicustomer Details | D31: Always | F31: RC_CUSTOMER_ACCOUNT.json | G31: PHONE_NUMBERS_RESI | H31: 8 | I31: identity | J31: Y | K31: Clean numeric text. | N31: =IFERROR(XLOOKUP($F31&"."&$G31,CaseSource!$A$2:$A$371,CaseSource!$B$2:$B$371,""),"")
A32: primaryMobileAlt | D32: Always | F32: CPV_DETAIL.json | G32: RESI_PHONE2 | H32: 1 | I32: identity | J32: Y | K32: First number different from primary. | N32: =IFERROR(XLOOKUP($F32&"."&$G32,CaseSource!$A$2:$A$371,CaseSource!$B$2:$B$371,""),"")
A33: primaryMobileAlt | D33: Always | F33: GURANTOR.json | G33: RESI_PHONE | H33: 2 | I33: identity | J33: Y | K33: First number different from primary. | N33: =IFERROR(XLOOKUP($F33&"."&$G33,CaseSource!$A$2:$A$371,CaseSource!$B$2:$B$371,""),"")
A34: primaryMobileAlt | D34: Always | F34: GURANTOR.json | G34: OFF_PHONE | H34: 3 | I34: identity | J34: Y | K34: First number different from primary. | N34: =IFERROR(XLOOKUP($F34&"."&$G34,CaseSource!$A$2:$A$371,CaseSource!$B$2:$B$371,""),"")
A35: primaryMobileAlt | D35: Always | F35: CPV_DETAIL.json | G35: OFF_PHONE1 | H35: 4 | I35: identity | J35: Y | K35: First number different from primary. | N35: =IFERROR(XLOOKUP($F35&"."&$G35,CaseSource!$A$2:$A$371,CaseSource!$B$2:$B$371,""),"")
A36: email | B36: Profile | C36: Emicustomer Details | D36: Always | F36: CPV_DETAIL.json | G36: E_MAIL | H36: 1 | I36: identity | J36: Y | K36: clean text | N36: =IFERROR(XLOOKUP($F36&"."&$G36,CaseSource!$A$2:$A$371,CaseSource!$B$2:$B$371,""),"")
A37: email | B37: Profile | C37: Emicustomer Details | D37: Always | F37: CPV_DETAIL.json | G37: EMAIL_ADDRESS | H37: 2 | I37: identity | J37: Y | K37: clean text | N37: =IFERROR(XLOOKUP($F37&"."&$G37,CaseSource!$A$2:$A$371,CaseSource!$B$2:$B$371,""),"")
A38: panNumber | B38: Header / Shared | C38: Loan Sticky Header | D38: Always | F38: CPV_DETAIL.json | G38: PAN_NUMBER | H38: 1 | I38: identity | J38: Y | K38: clean text | N38: =IFERROR(XLOOKUP($F38&"."&$G38,CaseSource!$A$2:$A$371,CaseSource!$B$2:$B$371,""),"")
A39: gstNumber | D39: Always | F39: CPV_DETAIL.json | G39: GST_NUMBER | H39: 1 | I39: identity | J39: Y | K39: company flow only | N39: =IFERROR(XLOOKUP($F39&"."&$G39,CaseSource!$A$2:$A$371,CaseSource!$B$2:$B$371,""),"")
A40: gstNumber | D40: Always | F40: RC_CUSTOMER_ACCOUNT.json | G40: GST_NUMBER | H40: 2 | I40: identity | J40: Y | K40: company flow only | N40: =IFERROR(XLOOKUP($F40&"."&$G40,CaseSource!$A$2:$A$371,CaseSource!$B$2:$B$371,""),"")
A41: residenceAddress | B41: Pre-File | C41: Loan Sticky Header | D41: Always | F41: CPV_DETAIL.json | G41: OFF_ADD1 | H41: 1 | I41: identity | J41: Y | K41: joined cleaned text | N41: =IFERROR(XLOOKUP($F41&"."&$G41,CaseSource!$A$2:$A$371,CaseSource!$B$2:$B$371,""),"")
A42: residenceAddress | B42: Pre-File | C42: Loan Sticky Header | D42: Always | F42: CPV_DETAIL.json | G42: RESI_ADD1 | H42: 2 | I42: identity | J42: Y | K42: joined cleaned text | N42: =IFERROR(XLOOKUP($F42&"."&$G42,CaseSource!$A$2:$A$371,CaseSource!$B$2:$B$371,""),"")
A43: residenceAddress | B43: Pre-File | C43: Loan Sticky Header | D43: Always | F43: CPV_DETAIL.json | G43: RESIDENCE_ADDRESS | H43: 3 | I43: identity | J43: Y | K43: joined cleaned text | N43: =IFERROR(XLOOKUP($F43&"."&$G43,CaseSource!$A$2:$A$371,CaseSource!$B$2:$B$371,""),"")
A44: residenceAddress | B44: Pre-File | C44: Loan Sticky Header | D44: Always | F44: CPV_DETAIL.json | G44: RESI_ADDRESS | H44: 4 | I44: identity | J44: Y | K44: joined cleaned text | N44: =IFERROR(XLOOKUP($F44&"."&$G44,CaseSource!$A$2:$A$371,CaseSource!$B$2:$B$371,""),"")
A45: residenceAddress | B45: Pre-File | C45: Loan Sticky Header | D45: Always | F45: RC_CUSTOMER_ACCOUNT.json | G45: RESI_ADDRESS | H45: 5 | I45: identity | J45: Y | K45: joined cleaned text | N45: =IFERROR(XLOOKUP($F45&"."&$G45,CaseSource!$A$2:$A$371,CaseSource!$B$2:$B$371,""),"")
A46: residenceAddress | B46: Pre-File | C46: Loan Sticky Header | D46: Always | F46: RC_CUSTOMER_ACCOUNT.json | G46: CUST_ADDRESS | H46: 6 | I46: identity | J46: Y | K46: joined cleaned text | N46: =IFERROR(XLOOKUP($F46&"."&$G46,CaseSource!$A$2:$A$371,CaseSource!$B$2:$B$371,""),"")
...

Sheet NewFieldCatalog
A1: new_field | B1: new_type | C1: new_page | D1: new_section | E1: applies_when | F1: flow_notes | G1: new_source_files
A2: aadhaarCardDocUrl | B2: string | C2: Post-File | D2: Documents List | E2: Always | G2: src/modules/loans/components/loan-form/post-file/DocumentsList.jsx; src/modules/loans/components/loan-form/post-file/PostFileDocumentManagement.jsx
A3: aadhaarNumber | B3: string | C3: Header / Shared | D3: Loan Sticky Header | E3: Always | G3: src/modules/loans/components/LoanStickyHeader.jsx
A4: accessoriesAmount | B4: number | C4: Pre-File | D4: Post File Vehicle Verification | E4: Always | G4: src/modules/loans/components/loan-form/post-file/PostFileVehicleVerification.jsx; src/modules/loans/components/loan-form/pre-file/VehiclePricingLoanDetails.jsx
A5: accountNumber | B5: number | C5: Pre-File | D5: Post File Dispatch And Records | E5: Always | G5: src/modules/loans/components/loan-form/post-file/PostFileDispatchAndRecords.jsx; src/modules/loans/components/loan-form/pre-file/IncomeBankingDetailsPreFile.jsx
A6: accountSinceYears | B6: number | C6: Pre-File | D6: Income Banking Details Pre File | E6: Always | G6: src/modules/loans/components/loan-form/pre-file/IncomeBankingDetailsPreFile.jsx
A7: accountType | B7: string | C7: Pre-File | D7: Income Banking Details Pre File | E7: Always | G7: src/modules/loans/components/loan-form/pre-file/IncomeBankingDetailsPreFile.jsx
A8: addressProofDocUrl | B8: string | C8: Post-File | D8: Documents List | E8: Always | G8: src/modules/loans/components/loan-form/post-file/DocumentsList.jsx; src/modules/loans/components/loan-form/post-file/PostFileDocumentManagement.jsx
A9: addressProofNumber | B9: boolean | C9: Pre-File | D9: Personal Details Pre File | E9: Always | G9: src/modules/loans/components/loan-form/pre-file/PersonalDetailsPreFile.jsx
A10: addressProofType | B10: boolean | C10: Pre-File | D10: Personal Details Pre File | E10: Always | G10: src/modules/loans/components/loan-form/pre-file/PersonalDetailsPreFile.jsx
A11: addressType | B11: number | C11: Pre-File | D11: Personal Details Pre File | E11: Always | G11: src/modules/loans/components/loan-form/pre-file/PersonalDetailsPreFile.jsx
A12: advanceEmi | B12: number | C12: Pre-File | D12: Vehicle Pricing Loan Details | E12: Always | G12: src/modules/loans/components/loan-form/pre-file/VehiclePricingLoanDetails.jsx
A13: applicantType | B13: string | C13: Profile | D13: Lead Details | E13: Always | F13: Individual vs Company changes form visibility and required sections. | G13: src/modules/loans/components/loan-form/customer-profile/LeadDetails.jsx; src/modules/loans/components/loan-form/pre-file/AuthorisedSignatorySection.jsx; src/modules/loans/components/loan-form/pre-file/OccupationalDetailsPreFile.jsx
A14: approval_approvalDate | B14: string | C14: Approval | D14: Loan Form With Steps | E14: Financed flow | F14: For legacy migration, use disbursement date when explicit approval date is absent. | G14: src/modules/loans/components/LoanFormWithSteps.jsx; src/modules/loans/components/loan-form/loan-approval/LoanApprovalStep.jsx
A15: approval_bankId | B15: string | C15: Approval | D15: Loan Form With Steps | E15: Always | G15: src/modules/loans/components/LoanFormWithSteps.jsx; src/modules/loans/components/loan-form/loan-approval/LoanApprovalStep.jsx
A16: approval_bankName | B16: string | C16: Approval | D16: Loan Form With Steps | E16: Always | G16: src/modules/loans/components/LoanFormWithSteps.jsx; src/modules/loans/components/LoanStickyHeader.jsx; src/modules/loans/components/loan-form/loan-approval/LoanApprovalStep.jsx; src/modules/loans/components/loan-form/payout/PayoutSection.jsx; src/modules/loans/components/loan-form/post-file/PostFileApprovalDetails.jsx; src/modules/loans/components/loan-form/vehicle-delivery/VehicleDeliveryStep.jsx
A17: approval_banksData | B17: string | C17: Shared | D17: Loan Form With Steps | E17: Always | G17: src/modules/loans/components/LoanFormWithSteps.jsx
A18: approval_breakup_creditAssured | B18: string | C18: Approval | D18: Loan Form With Steps | E18: Always | G18: src/modules/loans/components/LoanFormWithSteps.jsx; src/modules/loans/components/loan-form/loan-approval/LoanApprovalStep.jsx
A19: approval_breakup_ewFinance | B19: string | C19: Approval | D19: Loan Form With Steps | E19: Always | G19: src/modules/loans/components/LoanFormWithSteps.jsx; src/modules/loans/components/loan-form/loan-approval/LoanApprovalStep.jsx
A20: approval_breakup_insuranceFinance | B20: string | C20: Approval | D20: Loan Form With Steps | E20: Always | G20: src/modules/loans/components/LoanFormWithSteps.jsx; src/modules/loans/components/loan-form/loan-approval/LoanApprovalStep.jsx
A21: approval_breakup_netLoanApproved | B21: string | C21: Approval | D21: Loan Form With Steps | E21: Always | G21: src/modules/loans/components/LoanFormWithSteps.jsx; src/modules/loans/components/loan-form/loan-approval/LoanApprovalStep.jsx; src/modules/loans/components/loan-form/payout/PayoutSection.jsx
A22: approval_disbursedDate | B22: string | C22: Approval | D22: Loan Form With Steps | E22: Financed flow | F22: Critical for post-file/delivery unlock in migrated records. | G22: src/modules/loans/components/LoanFormWithSteps.jsx; src/modules/loans/components/loan-form/loan-approval/LoanApprovalStep.jsx; src/modules/loans/components/loan-form/post-file/PostFileApprovalDetails.jsx
A23: approval_loanAmountApproved | B23: string | C23: Approval | D23: Loan Form With Steps | E23: Always | G23: src/modules/loans/components/LoanFormWithSteps.jsx; src/modules/loans/components/LoanStickyHeader.jsx; src/modules/loans/components/loan-form/loan-approval/LoanApprovalStep.jsx; src/modules/loans/components/loan-form/post-file/PostFileApprovalDetails.jsx
A24: approval_loanAmountDisbursed | B24: string | C24: Approval | D24: Loan Form With Steps | E24: Always | G24: src/modules/loans/components/LoanFormWithSteps.jsx; src/modules/loans/components/loan-form/loan-approval/LoanApprovalStep.jsx; src/modules/loans/components/loan-form/payout/PayoutSection.jsx; src/modules/loans/components/loan-form/post-file/PostFileApprovalDetails.jsx
A25: approval_processingFees | B25: string | C25: Approval | D25: Loan Form With Steps | E25: Always | G25: src/modules/loans/components/LoanFormWithSteps.jsx; src/modules/loans/components/loan-form/loan-approval/LoanApprovalStep.jsx; src/modules/loans/components/loan-form/post-file/PostFileApprovalDetails.jsx
A26: approval_roi | B26: string | C26: Approval | D26: Loan Form With Steps | E26: Always | G26: src/modules/loans/components/LoanFormWithSteps.jsx; src/modules/loans/components/loan-form/loan-approval/LoanApprovalStep.jsx; src/modules/loans/components/loan-form/post-file/PostFileApprovalDetails.jsx
A27: approval_status | B27: string | C27: Approval | D27: Loan Form With Steps | E27: Financed flow | F27: Set approved/disbursed correctly; downstream stages depend on it. | G27: src/modules/loans/components/LoanFormWithSteps.jsx; src/modules/loans/components/LoanStickyHeader.jsx; src/modules/loans/components/loan-form/loan-approval/LoanApprovalStep.jsx; src/modules/loans/components/loan-form/payout/PayoutSection.jsx; src/modules/loans/components/loan-form/post-file/PostFileApprovalDetails.jsx
A28: approval_statusHistory | B28: string | C28: Approval | D28: Loan Approval Step | E28: Always | G28: src/modules/loans/components/loan-form/loan-approval/LoanApprovalStep.jsx
A29: approval_tenureMonths | B29: string | C29: Approval | D29: Loan Form With Steps | E29: Always | G29: src/modules/loans/components/LoanFormWithSteps.jsx; src/modules/loans/components/LoanStickyHeader.jsx; src/modules/loans/components/loan-form/loan-approval/LoanApprovalStep.jsx; src/modules/loans/components/loan-form/post-file/PostFileApprovalDetails.jsx
A30: bankName | B30: string | C30: Pre-File | D30: Loan Form With Steps | E30: Always | G30: src/modules/loans/components/LoanFormWithSteps.jsx; src/modules/loans/components/loan-form/post-file/PostFileDispatchAndRecords.jsx; src/modules/loans/components/loan-form/pre-file/IncomeBankingDetailsPreFile.jsx
A31: billDate | B31: string | C31: Payout | D31: Bill Printing Modal | E31: Always | G31: src/modules/loans/components/loan-form/payout/BillPrintingModal.jsx
A32: billNumber | B32: string | C32: Payout | D32: Bill Printing Modal | E32: Always | G32: src/modules/loans/components/loan-form/payout/BillPrintingModal.jsx
A33: boughtInYear | B33: number | C33: Pre-File | D33: Post File Vehicle Verification | E33: Always | G33: src/modules/loans/components/loan-form/post-file/PostFileVehicleVerification.jsx; src/modules/loans/components/loan-form/pre-file/VehiclePricingLoanDetails.jsx
A34: branch | B34: number | C34: Pre-File | D34: Post File Dispatch And Records | E34: Always | G34: src/modules/loans/components/loan-form/post-file/PostFileDispatchAndRecords.jsx; src/modules/loans/components/loan-form/pre-file/IncomeBankingDetailsPreFile.jsx
A35: bulk_next_action | B35: string | C35: Payout | D35: Payout Receivables Dashboard | E35: Always | G35: src/modules/loans/components/loan-form/payout/PayoutReceivablesDashboard.jsx
A36: bulk_priority | B36: string | C36: Payout | D36: Payout Receivables Dashboard | E36: Always | G36: src/modules/loans/components/loan-form/payout/PayoutReceivablesDashboard.jsx
A37: bulk_remarks | B37: string | C37: Payout | D37: Payout Receivables Dashboard | E37: Always | G37: src/modules/loans/components/loan-form/payout/PayoutReceivablesDashboard.jsx
A38: businessNature | B38: string | C38: Pre-File | D38: Occupational Details Pre File | E38: Always | G38: src/modules/loans/components/loan-form/pre-file/OccupationalDetailsPreFile.jsx
A39: caseType | B39: string | C39: Header / Shared | D39: Loan Sticky Header | E39: Always | G39: src/modules/loans/components/LoanStickyHeader.jsx
... A82: createdAt | B82: string | C82: Header / Shared | D82: Loan Form With Steps | E82: Always | G82: src/modules/loans/components/LoanFormWithSteps.jsx; src/modules/loans/components/LoanStickyHeader.jsx
...

Sheet LegacyCatalog
A1: legacy_file | B1: legacy_field
A2: AUTH_SIGNATORY.json | B2: ACCOUNT_NUMBER_TYPE
A3: AUTH_SIGNATORY.json | B3: ADD1
A4: AUTH_SIGNATORY.json | B4: ADD2
A5: AUTH_SIGNATORY.json | B5: AUTH_AADHAAR_NUMBER
A6: AUTH_SIGNATORY.json | B6: CITY
A7: AUTH_SIGNATORY.json | B7: CPV_ACCOUNT_NO
A8: AUTH_SIGNATORY.json | B8: DATA_LOCATION_CODE
A9: AUTH_SIGNATORY.json | B9: DATE_OF_BIRTH
A10: AUTH_SIGNATORY.json | B10: DESIGNATION
A11: AUTH_SIGNATORY.json | B11: FAX
A12: AUTH_SIGNATORY.json | B12: HP_GROUP
... A409: RC_SOURCE_REFERENCE.json | B409: TEMP_CUST_CODE

Sheet DropdownData
A1: legacy_files | B1: AUTH_SIGNATORY.json | C1: CPV_DETAIL.json | D1: CUSTOMER_BANK.json | E1: GURANTOR.json | F1: RC_CUSTOMER_ACCOUNT.json | G1: RC_DOC_DESPATCH_MASTER.json | H1: RC_INSTRUMENT_DETAIL.json | I1: RC_RC_INV_RECEIVING_DETAIL.json | J1: RC_RC_INV_STATUS.json | K1: RC_SOURCE_REFERENCE.json
A2: AUTH_SIGNATORY.json | B2: ACCOUNT_NUMBER_TYPE | C2: AADHAAR_NUMBER | D2: ACCOUNT_NUMBER_TYPE | E2: ACCOUNT_NUMBER_TYPE | F2: ACCOUNT_STATUS | G2: DATA_LOCATION_CODE | H2: ACCOUNT_NUMBER | I2: CHASIS_NUMBER | J2: AGEING_FOR_BANK | K2: DATA_LOCATION_CODE
A3: CPV_DETAIL.json | B3: ADD1 | C3: ACCOUNT_NUMBER_TYPE | D3: BANK_ADDRESS | E3: ANNUAL_INCOME | F3: ADDRESS_FOR_REGISTER | G3: DATE_OF_DESP | H3: DATA_LOCATION_CODE | I3: DATA_LOCATION_CODE | J3: AGEING_FOR_US | K3: HP_GROUP
A4: CUSTOMER_BANK.json | B4: ADD2 | C4: ANNUAL_INCOME | D4: BANK_FAX | E4: CPV_ACCOUNT_NO | F4: ADDRESS_PROOF_FOR_REGISTRATION | G4: DESP_THROUGH | H4: DRAWN_ON | I4: DATE_OF_REGISTRATION | J4: CASE_TYPE_CODE | K4: PHONE_NUMBER
A5: GURANTOR.json | B5: AUTH_AADHAAR_NUMBER | C5: CAR_MODEL | D5: BANK_NAME | E5: DATA_LOCATION_CODE | F5: AGEING_FOR_BANK | G5: DESPATCH_ID | H5: ENTERED_BY | I5: DISPLACEMENT | J5: CHASIS_NUMBER | K5: REFERENCE_BY
A6: RC_CUSTOMER_ACCOUNT.json | B6: CITY | C6: CATEGORY | D6: BANK_PHONE | E6: DATE_OF_BIRTH | F6: AGEING_FOR_US | G6: DOC_DESP_AS | H6: ENTERED_ON_DATE | I6: ENGINE_NUMBER | J6: DATA_LOCATION_CODE | K6: TEMP_CUST_CODE
A7: RC_DOC_DESPATCH_MASTER.json | B7: CPV_ACCOUNT_NO | C7: CDB_ACCOUNT_NO | D7: CA_ACCOUNT_NO | E7: EDUCATION | F7: APPLIED_EMI | G7: DOCS_COLLECTED_BY | H7: HP_GROUP | I7: INV_RECEIVED_AS | J7: DATE_OF_DELIVERY
A8: RC_INSTRUMENT_DETAIL.json | B8: DATA_LOCATION_CODE | C8: CLS_REMARKS | D8: CPV_ACCOUNT_NO | E8: G_AADHAAR_NUMBER | F8: APPLIED_EMI_DUE_DATE | G8: DOCS_PREPARED_BY | H8: INSTRMNT_AMOUNT | I8: INV_RECEIVED_FROM | J8: DATE_OF_DISBURSE
A9: RC_RC_INV_RECEIVING_DETAIL.json | B9: DATE_OF_BIRTH | C9: CLS_STATUS | D9: DATA_LOCATION_CODE | E9: G_ICICI_ENTRY_NUMBER | F9: APPLIED_LOAN_AMOUNT | G9: TEMP_CUST_CODE | H9: INSTRMNT_BY_BORWR_GRNTR | I9: INV_RECEIVED_ON_DATE | J9: DATE_OF_REGISTRATION
A10: RC_RC_INV_STATUS.json | B10: DESIGNATION | C10: CPV_ACCOUNT_NO | D10: HP_GROUP | E10: HP_GROUP | F10: APPLIED_ROI | G10: TIME_OF_DESP | H10: INSTRMNT_DATE | I10: INVOICE_DATE | J10: ENGINE_NUMBER
A11: RC_SOURCE_REFERENCE.json | B11: FAX | C11: CPV_DATE | D11: OD_LIMIT | E11: MARITAL_STATUS | F11: APPLIED_TENOR | H11: INSTRMNT_FAVOURING | I11: INVOICE_NUMBER | J11: HP_GROUP
B12: HP_GROUP | C12: CPV_G_OFF_STATUS | D12: ORIGINAL_HP_GROUP | E12: MOBILE | F12: BANK_FILE_NUMBER | H12: INSTRMNT_NO | I12: LIEN_MARK | J12: INV_STATUS
B13: MOBILE | C13: CPV_G_RES_STATUS | D13: SB_ACCOUNT_NO | E13: NAME | F13: BORROWER_CATEGORY | H13: INSTRMNT_RECPT_ID_NO | I13: NO_OF_CYLINDERS | J13: INVOICE_DATE
B14: NAME | C14: CPV_MONTH_YEAR | E14: NO_OF_DEPEND | F14: BORROWER_RELATION | H14: INSTRMNT_TYPE | I14: ON_DATE | J14: INVOICE_NUMBER
B15: ORIGINAL_HP_GROUP | C15: CPV_OFF_STATUS | E15: OFF_ADD1 | F15: CASE_FOR_YEAR_MONTH | H15: LAST_UPDATE_ON_DATE | I15: RC_RECEIVED_AS | J15: IS_RC_DESPATCH_TO_BANK
B16: PHONE | C16: CPV_RES_STATUS | E16: OFF_ADD2 | F16: CASE_ORIGIN | H16: LAST_UPDATED_BY_USER | I16: RC_RECEIVED_FROM | J16: IS_VEHICLE_DELIVERED
B17: PIN | C17: CPV_SEND_AT_TIME | E17: OFF_CITY | F17: CASE_TYPE | H17: MICR_CODE | I17: RC_RECEIVED_ON_DATE | J17: LIEN_MARK
C18: CPV_SEND_ON_DATE | E18: OFF_FAX | F18: CASE_TYPE_CODE | H18: STATUS | I18: RECEIVING_NO | J18: MAKE_MODEL
C19: CREATED_BY_USER | E19: OFF_NAME | F19: CHANNEL_CODE | H19: STATUS_BY_USER | I19: REGD_NUMBER | J19: MANUFACTURER_CODE
C20: CREATED_ON_DATE | E20: OFF_PHONE | F20: CHASIS_NUMBER | H20: STATUS_ON_DATE | I20: SEATING_CAPACITY | J20: MFG_YEAR
C21: CREATED_ON_TIME | E21: OFF_PIN | F21: CLOSED_BY | H21: TEMP_CUST_CODE | I21: TEMP_CUST_CODE | J21: MODEL_CODE
C22: CUST_NAME_FIRST | E22: ORIGINAL_HP_GROUP | F22: CLOSEDBY_CODE | I22: UNLAIDEN_WEIGHT | J22: ORIGINAL_HP_GROUP
C23: CUST_NAME_LAST | E23: PROFESSION_TYPE | F23: CPV_ACCOUNT_NO | I23: USER_NAME | J23: OVERALL_STATUS
C24: CUST_NAME_MIDDLE | E24: RESI_ADD1 | F24: CPV_ACCOUNT_NUMBER_TYPE | J24: RC_STATUS
C25: CUSTOMER_NAME | E25: RESI_ADD2 | F25: CUST_CODE | J25: RC_STORAGE_NUMBER
C26: DATA_LOCATION_CODE | E26: RESI_CITY | F26: CUST_NAME | J26: REGD_NUMBER
C27: DATA_STATUS | E27: RESI_PHONE | F27: DATA_LOCATION_CODE | J27: TEMP_CUST_CODE
C28: DATE_OF_BIRTH | E28: RESI_PIN | F28: DATE_OF_APPROVAL_STATUS_TAKEN | J28: VARIANT_CODE
C29: DEALT_BY | E29: RESIDENCE_TYPE | F29: DATE_OF_DELIVERY
C30: DRIVING_LICENSE | E30: SEX | F30: DATE_OF_DESPATCH_FOR_APPROVAL
C31: E_MAIL | E31: VEHICLE_HAVE | F31: DATE_OF_DISBURSE
C32: EDUCATION | E32: VEHICLE_OWNERSHIP | F32: DATE_OF_FILE_DESPATCH
C33: EMAIL_ADDRESS | E33: YEARS_AT_PROFESSION | F33: DATE_WHEN_FILE_DESPATCH
C34: FATHERS_NAME_FIRST | E34: YEARS_AT_RESIDENCE | F34: DATE_WHEN_FILE_IN_BOOKING
C35: FATHERS_NAME_LAST | F35: DATE_WHEN_FILE_MOVED_TO_BANK
C36: FATHERS_NAME_MIDDLE | F36: DATE_WHEN_FILE_REACHED_AT_CPA
C37: FINANCER | F37: DATE_WHEN_FILE_RECEIVED
C38: GURANTOR_AVAILABLE | F38: DATE_WHEN_FILE_REJECT_WITHDRWN
C39: HEAD_NAME | F39: DEALER_CODE
C40: HIRE_TYPE | F40: DEALER_SUBVENTION
...

Sheet Instructions
A1: How to use this workbook
A3: 1. Open sheet 'MappingEditor'.
A4: 2. Columns 'applies_when' and 'flow_notes' explain conditional flow dependencies.
A5: 3. Each row is one mapping rule. Duplicate rows to add fallbacks for the same new_field.
A6: 4. Select 'legacy_file' from dropdown first, then 'legacy_field' from dependent dropdown.
A7: 5. Use fallback_priority: 1 (highest), 2, 3 ...
A8: 6. Set transform (identity, normalize_yes_no, to_date, to_number, concat, custom).
A9: 7. Set active = Y/N.
A10: 8. Important: keep Source vs Dealt By separate (sourceName <- SOURCE-like, dealtBy <- DEALT_BY-like).
A11: 9. Save workbook and run parser script to generate JSON mapping config.
A13: Parser command:
A14: python3 scripts/parse_mapping_workbook.py --workbook migration_analysis/loan_field_mapping_workbook.xlsx --out migration_analysis/loan_field_mapping_config.json
... A19: Workbook generated for case: 3000004231

Sheet UnmappedNewFields
A1: new_field | B1: new_page | C1: new_section | D1: status
A2: aadhaarCardDocUrl | B2: Post-File | C2: Documents List | D2: =IF((COUNTIFS(MappingEditor!$A:$A,$A2,MappingEditor!$J:$J,"Y")+COUNTIFS(FallbackEditor!$A:$A,$A2,FallbackEditor!$J:$J,"Y"))>0,"mapped","unmapped")
A3: aadhaarNumber | B3: Header / Shared | C3: Loan Sticky Header | D3: =IF((COUNTIFS(MappingEditor!$A:$A,$A3,MappingEditor!$J:$J,"Y")+COUNTIFS(FallbackEditor!$A:$A,$A3,FallbackEditor!$J:$J,"Y"))>0,"mapped","unmapped")
A4: accessoriesAmount | B4: Pre-File | C4: Post File Vehicle Verification | D4: =IF((COUNTIFS(MappingEditor!$A:$A,$A4,MappingEditor!$J:$J,"Y")+COUNTIFS(FallbackEditor!$A:$A,$A4,FallbackEditor!$J:$J,"Y"))>0,"mapped","unmapped")
A5: accountNumber | B5: Pre-File | C5: Post File Dispatch And Records | D5: =IF((COUNTIFS(MappingEditor!$A:$A,$A5,MappingEditor!$J:$J,"Y")+COUNTIFS(FallbackEditor!$A:$A,$A5,FallbackEditor!$J:$J,"Y"))>0,"mapped","unmapped")
A6: accountSinceYears | B6: Pre-File | C6: Income Banking Details Pre File | D6: =IF((COUNTIFS(MappingEditor!$A:$A,$A6,MappingEditor!$J:$J,"Y")+COUNTIFS(FallbackEditor!$A:$A,$A6,FallbackEditor!$J:$J,"Y"))>0,"mapped","unmapped")
A7: accountType | B7: Pre-File | C7: Income Banking Details Pre File | D7: =IF((COUNTIFS(MappingEditor!$A:$A,$A7,MappingEditor!$J:$J,"Y")+COUNTIFS(FallbackEditor!$A:$A,$A7,FallbackEditor!$J:$J,"Y"))>0,"mapped","unmapped")
A8: addressProofDocUrl | B8: Post-File | C8: Documents List | D8: =IF((COUNTIFS(MappingEditor!$A:$A,$A8,MappingEditor!$J:$J,"Y")+COUNTIFS(FallbackEditor!$A:$A,$A8,FallbackEditor!$J:$J,"Y"))>0,"mapped","unmapped")
A9: addressProofNumber | B9: Pre-File | C9: Personal Details Pre File | D9: =IF((COUNTIFS(MappingEditor!$A:$A,$A9,MappingEditor!$J:$J,"Y")+COUNTIFS(FallbackEditor!$A:$A,$A9,FallbackEditor!$J:$J,"Y"))>0,"mapped","unmapped")
A10: addressProofType | B10: Pre-File | C10: Personal Details Pre File | D10: =IF((COUNTIFS(MappingEditor!$A:$A,$A10,MappingEditor!$J:$J,"Y")+COUNTIFS(FallbackEditor!$A:$A,$A10,FallbackEditor!$J:$J,"Y"))>0,"mapped","unmapped")
A11: addressType | B11: Pre-File | C11: Personal Details Pre File | D11: =IF((COUNTIFS(MappingEditor!$A:$A,$A11,MappingEditor!$J:$J,"Y")+COUNTIFS(FallbackEditor!$A:$A,$A11,FallbackEditor!$J:$J,"Y"))>0,"mapped","unmapped")
A12: advanceEmi | B12: Pre-File | C12: Vehicle Pricing Loan Details | D12: =IF((COUNTIFS(MappingEditor!$A:$A,$A12,MappingEditor!$J:$J,"Y")+COUNTIFS(FallbackEditor!$A:$A,$A12,FallbackEditor!$J:$J,"Y"))>0,"mapped","unmapped")
A13: applicantType | B13: Profile | C13: Lead Details | D13: =IF((COUNTIFS(MappingEditor!$A:$A,$A13,MappingEditor!$J:$J,"Y")+COUNTIFS(FallbackEditor!$A:$A,$A13,FallbackEditor!$J:$J,"Y"))>0,"mapped","unmapped")
... A324: yearsInCurrentHouse | B324: Profile | C324: Personal Details Simplified | D324: =IF((COUNTIFS(MappingEditor!$A:$A,$A324,MappingEditor!$J:$J,"Y")+COUNTIFS(FallbackEditor!$A:$A,$A324,FallbackEditor!$J:$J,"Y"))>0,"mapped","unmapped")

Sheet UnmappedLegacyFields
A1: legacy_file | B1: legacy_field | C1: status
A2: AUTH_SIGNATORY.json | B2: ACCOUNT_NUMBER_TYPE | C2: =IF((COUNTIFS(MappingEditor!$F:$F,$A2,MappingEditor!$G:$G,$B2,MappingEditor!$J:$J,"Y")+COUNTIFS(FallbackEditor!$G:$G,$A2,FallbackEditor!$H:$H,$B2,FallbackEditor!$J:$J,"Y"))>0,"mapped","unmapped")
A3: AUTH_SIGNATORY.json | B3: ADD1 | C3: =IF((COUNTIFS(MappingEditor!$F:$F,$A3,MappingEditor!$G:$G,$B3,MappingEditor!$J:$J,"Y")+COUNTIFS(FallbackEditor!$G:$G,$A3,FallbackEditor!$H:$H,$B3,FallbackEditor!$J:$J,"Y"))>0,"mapped","unmapped")
A4: AUTH_SIGNATORY.json | B4: ADD2 | C4: =IF((COUNTIFS(MappingEditor!$F:$F,$A4,MappingEditor!$G:$G,$B4,MappingEditor!$J:$J,"Y")+COUNTIFS(FallbackEditor!$G:$G,$A4,FallbackEditor!$H:$H,$B4,FallbackEditor!$J:$J,"Y"))>0,"mapped","unmapped")
A5: AUTH_SIGNATORY.json | B5: AUTH_AADHAAR_NUMBER | C5: =IF((COUNTIFS(MappingEditor!$F:$F,$A5,MappingEditor!$G:$G,$B5,MappingEditor!$J:$J,"Y")+COUNTIFS(FallbackEditor!$G:$G,$A5,FallbackEditor!$H:$H,$B5,FallbackEditor!$J:$J,"Y"))>0,"mapped","unmapped")
A6: AUTH_SIGNATORY.json | B6: CITY | C6: =IF((COUNTIFS(MappingEditor!$F:$F,$A6,MappingEditor!$G:$G,$B6,MappingEditor!$J:$J,"Y")+COUNTIFS(FallbackEditor!$G:$G,$A6,FallbackEditor!$H:$H,$B6,FallbackEditor!$J:$J,"Y"))>0,"mapped","unmapped")
A7: AUTH_SIGNATORY.json | B7: CPV_ACCOUNT_NO | C7: =IF((COUNTIFS(MappingEditor!$F:$F,$A7,MappingEditor!$G:$G,$B7,MappingEditor!$J:$J,"Y")+COUNTIFS(FallbackEditor!$G:$G,$A7,FallbackEditor!$H:$H,$B7,FallbackEditor!$J:$J,"Y"))>0,"mapped","unmapped")
A8: AUTH_SIGNATORY.json | B8: DATA_LOCATION_CODE | C8: =IF((COUNTIFS(MappingEditor!$F:$F,$A8,MappingEditor!$G:$G,$B8,MappingEditor!$J:$J,"Y")+COUNTIFS(FallbackEditor!$G:$G,$A8,FallbackEditor!$H:$H,$B8,FallbackEditor!$J:$J,"Y"))>0,"mapped","unmapped")
A9: AUTH_SIGNATORY.json | B9: DATE_OF_BIRTH | C9: =IF((COUNTIFS(MappingEditor!$F:$F,$A9,MappingEditor!$G:$G,$B9,MappingEditor!$J:$J,"Y")+COUNTIFS(FallbackEditor!$G:$G,$A9,FallbackEditor!$H:$H,$B9,FallbackEditor!$J:$J,"Y"))>0,"mapped","unmapped")
A10: AUTH_SIGNATORY.json | B10: DESIGNATION | C10: =IF((COUNTIFS(MappingEditor!$F:$F,$A10,MappingEditor!$G:$G,$B10,MappingEditor!$J:$J,"Y")+COUNTIFS(FallbackEditor!$G:$G,$A10,FallbackEditor!$H:$H,$B10,FallbackEditor!$J:$J,"Y"))>0,"mapped","unmapped")
A11: AUTH_SIGNATORY.json | B11: FAX | C11: =IF((COUNTIFS(MappingEditor!$F:$F,$A11,MappingEditor!$G:$G,$B11,MappingEditor!$J:$J,"Y")+COUNTIFS(FallbackEditor!$G:$G,$A11,FallbackEditor!$H:$H,$B11,FallbackEditor!$J:$J,"Y"))>0,"mapped","unmapped")
A12: AUTH_SIGNATORY.json | B12: HP_GROUP | C12: =IF((COUNTIFS(MappingEditor!$F:$F,$A12,MappingEditor!$G:$G,$B12,MappingEditor!$J:$J,"Y")+COUNTIFS(FallbackEditor!$G:$G,$A12,FallbackEditor!$H:$H,$B12,FallbackEditor!$J:$J,"Y"))>0,"mapped","unmapped")
A13: AUTH_SIGNATORY.json | B13: MOBILE | C13: =IF((COUNTIFS(MappingEditor!$F:$F,$A13,MappingEditor!$G:$G,$B13,MappingEditor!$J:$J,"Y")+COUNTIFS(FallbackEditor!$G:$G,$A13,FallbackEditor!$H:$H,$B13,FallbackEditor!$J:$J,"Y"))>0,"mapped","unmapped")
... A409: RC_SOURCE_REFERENCE.json | B409: TEMP_CUST_CODE | C409: =IF((COUNTIFS(MappingEditor!$F:$F,$A409,MappingEditor!$G:$G,$B409,MappingEditor!$J:$J,"Y")+COUNTIFS(FallbackEditor!$G:$G,$A409,FallbackEditor!$H:$H,$B409,FallbackEditor!$J:$J,"Y"))>0,"mapped","unmapped")

Sheet FallbackEditor
A1: new_field | B1: new_page | C1: new_section | D1: applies_when | E1: flow_notes | F1: fallback_priority | G1: legacy_file | H1: legacy_field | I1: transform | J1: active | K1: notes | L1: case_value_preview
A2: accountNumber | B2: Pre-File | C2: Post File Dispatch And Records | D2: Always | F2: 1 | G2: CUSTOMER_BANK.json | H2: CA_ACCOUNT_NO | I2: identity | J2: Y | K2: clean | L2: =IFERROR(XLOOKUP($G2&"."&$H2,CaseSource!$A$2:$A$371,CaseSource!$B$2:$B$371,""),"")
A3: accountNumber | B3: Pre-File | C3: Post File Dispatch And Records | D3: Always | F3: 2 | G3: CUSTOMER_BANK.json | H3: SB_ACCOUNT_NO | I3: identity | J3: Y | K3: clean | L3: =IFERROR(XLOOKUP($G3&"."&$H3,CaseSource!$A$2:$A$371,CaseSource!$B$2:$B$371,""),"")
A4: addressProofNumber | B4: Pre-File | C4: Personal Details Pre File | D4: Always | F4: 1 | G4: CPV_DETAIL.json | H4: AADHAAR_NUMBER | I4: identity | J4: Y | K4: clean | L4: =IFERROR(XLOOKUP($G4&"."&$H4,CaseSource!$A$2:$A$371,CaseSource!$B$2:$B$371,""),"")
A5: applicantType | B5: Profile | C5: Lead Details | D5: Always | E5: Individual vs Company changes form visibility and required sections. | F5: 1 | G5: CPV_DETAIL.json | H5: HIRE_TYPE | I5: identity | J5: Y | K5: `normalizeApplicantType(...)` => `Individual`/`Company`. | L5: =IFERROR(XLOOKUP($G5&"."&$H5,CaseSource!$A$2:$A$371,CaseSource!$B$2:$B$371,""),"")
A6: approval_approvalDate | B6: Approval | C6: Loan Form With Steps | D6: Financed flow | E6: For legacy migration, use disbursement date when explicit approval date is absent. | F6: 1 | G6: RC_CUSTOMER_ACCOUNT.json | H6: DATE_OF_DISBURSE | I6: identity | J6: Y | K6: ISO | L6: =IFERROR(XLOOKUP($G6&"."&$H6,CaseSource!$A$2:$A$371,CaseSource!$B$2:$B$371,""),"")
A7: approval_approvalDate | B7: Approval | C7: Loan Form With Steps | D7: Financed flow | E7: For legacy migration, use disbursement date when explicit approval date is absent. | F7: 2 | G7: RC_RC_INV_STATUS.json | H7: DATE_OF_DISBURSE | I7: identity | J7: Y | K7: ISO | L7: =IFERROR(XLOOKUP($G7&"."&$H7,CaseSource!$A$2:$A$371,CaseSource!$B$2:$B$371,""),"")
A8: approval_approvalDate | B8: Approval | C8: Loan Form With Steps | D8: Financed flow | E8: For legacy migration, use disbursement date when explicit approval date is absent. | F8: 3 | G8: RC_CUSTOMER_ACCOUNT.json | H8: DATE_OF_FILE_DESPATCH | I8: identity | J8: Y | K8: ISO | L8: =IFERROR(XLOOKUP($G8&"."&$H8,CaseSource!$A$2:$A$371,CaseSource!$B$2:$B$371,""),"")
A9: approval_approvalDate | B9: Approval | C9: Loan Form With Steps | D9: Financed flow | E9: For legacy migration, use disbursement date when explicit approval date is absent. | F9: 4 | G9: CPV_DETAIL.json | H9: CPV_DATE | I9: identity | J9: Y | K9: ISO | L9: =IFERROR(XLOOKUP($G9&"."&$H9,CaseSource!$A$2:$A$371,CaseSource!$B$2:$B$371,""),"")
A10: approval_bankName` / `postfile_bankName | D10: Always | F10: 1 | G10: RC_CUSTOMER_ACCOUNT.json | H10: HP_TO | I10: identity | J10: Y | K10: bank normalization | L10: =IFERROR(XLOOKUP($G10&"."&$H10,CaseSource!$A$2:$A$371,CaseSource!$B$2:$B$371,""),"")
A11: approval_bankName` / `postfile_bankName | D11: Always | F11: 2 | G11: CPV_DETAIL.json | H11: FINANCER | I11: identity | J11: Y | K11: bank normalization | L11: =IFERROR(XLOOKUP($G11&"."&$H11,CaseSource!$A$2:$A$371,CaseSource!$B$2:$B$371,""),"")
A12: approval_disbursedDate` / `disbursement_date | D12: Always | F12: 1 | G12: RC_CUSTOMER_ACCOUNT.json | H12: DATE_OF_DISBURSE | I12: identity | J12: Y | K12: date | L12: =IFERROR(XLOOKUP($G12&"."&$H12,CaseSource!$A$2:$A$371,CaseSource!$B$2:$B$371,""),"")
A13: approval_disbursedDate` / `disbursement_date | D13: Always | F13: 2 | G13: RC_RC_INV_STATUS.json | H13: DATE_OF_DISBURSE | I13: identity | J13: Y | K13: date | L13: =IFERROR(XLOOKUP($G13&"."&$H13,CaseSource!$A$2:$A$371,CaseSource!$B$2:$B$371,""),"")
A14: approval_loanAmountApproved` / `postfile_loanAmountApproved | D14: Always | F14: 1 | G14: RC_CUSTOMER_ACCOUNT.json | H14: LOAN_AMOUNT | I14: identity | J14: Y | K14: numeric | L14: =IFERROR(XLOOKUP($G14&"."&$H14,CaseSource!$A$2:$A$371,CaseSource!$B$2:$B$371,""),"")
A15: approval_loanAmountApproved` / `postfile_loanAmountApproved | D15: Always | F15: 2 | G15: CPV_DETAIL.json | H15: LOAN_EXPECTED | I15: identity | J15: Y | K15: numeric | L15: =IFERROR(XLOOKUP($G15&"."&$H15,CaseSource!$A$2:$A$371,CaseSource!$B$2:$B$371,""),"")
A16: approval_roi` / `postfile_roi | D16: Always | F16: 1 | G16: RC_CUSTOMER_ACCOUNT.json | H16: ROI | I16: identity | J16: Y | K16: numeric | L16: =IFERROR(XLOOKUP($G16&"."&$H16,CaseSource!$A$2:$A$371,CaseSource!$B$2:$B$371,""),"")
A17: approval_tenureMonths` / `postfile_tenureMonths | D17: Always | F17: 1 | G17: RC_CUSTOMER_ACCOUNT.json | H17: TENOR | I17: identity | J17: Y | K17: numeric | L17: =IFERROR(XLOOKUP($G17&"."&$H17,CaseSource!$A$2:$A$371,CaseSource!$B$2:$B$371,""),"")
A18: approval_tenureMonths` / `postfile_tenureMonths | D18: Always | F18: 2 | G18: CPV_DETAIL.json | H18: TENDOR | I18: identity | J18: Y | K18: numeric | L18: =IFERROR(XLOOKUP($G18&"."&$H18,CaseSource!$A$2:$A$371,CaseSource!$B$2:$B$371,""),"")
A19: bankName | B19: Pre-File | C19: Loan Form With Steps | D19: Always | F19: 1 | G19: CUSTOMER_BANK.json | H19: BANK_NAME | I19: identity | J19: Y | K19: normalized bank name | L19: =IFERROR(XLOOKUP($G19&"."&$H19,CaseSource!$A$2:$A$371,CaseSource!$B$2:$B$371,""),"")
A20: boughtInYear | B20: Pre-File | C20: Post File Vehicle Verification | D20: Always | F20: 1 | G20: RC_CUSTOMER_ACCOUNT.json | H20: BOUGHT_IN_YEAR | I20: identity | J20: Y | K20: parse 4-digit/2-digit year normalization | L20: =IFERROR(XLOOKUP($G20&"."&$H20,CaseSource!$A$2:$A$371,CaseSource!$B$2:$B$371,""),"")
A21: boughtInYear | B21: Pre-File | C21: Post File Vehicle Verification | D21: Always | F21: 2 | G21: RC_CUSTOMER_ACCOUNT.json | H21: VEHICLE_YEAR | I21: identity | J21: Y | K21: parse 4-digit/2-digit year normalization | L21: =IFERROR(XLOOKUP($G21&"."&$H21,CaseSource!$A$2:$A$371,CaseSource!$B$2:$B$371,""),"")
A22: boughtInYear | B22: Pre-File | C22: Post File Vehicle Verification | D22: Always | F22: 3 | G22: CPV_DETAIL.json | H22: BOUGHT_IN_YEAR | I22: identity | J22: Y | K22: parse 4-digit/2-digit year normalization | L22: =IFERROR(XLOOKUP($G22&"."&$H22,CaseSource!$A$2:$A$371,CaseSource!$B$2:$B$371,""),"")
A23: branch | B23: Pre-File | C23: Post File Dispatch And Records | D23: Always | F23: 1 | G23: CUSTOMER_BANK.json | H23: BANK_ADDRESS | I23: identity | J23: Y | K23: clean | L23: =IFERROR(XLOOKUP($G23&"."&$H23,CaseSource!$A$2:$A$371,CaseSource!$B$2:$B$371,""),"")
A24: businessNature | B24: Pre-File | C24: Occupational Details Pre File | D24: Always | F24: 1 | G24: CPV_DETAIL.json | H24: ORGANISATION_TYPE | I24: identity | J24: Y | K24: multi-value combined | L24: =IFERROR(XLOOKUP($G24&"."&$H24,CaseSource!$A$2:$A$371,CaseSource!$B$2:$B$371,""),"")
A25: city | B25: Pre-File | C25: Loan Sticky Header | D25: Always | F25: 1 | G25: CPV_DETAIL.json | H25: OFF_CITY | I25: identity | J25: Y | K25: clean | L25: =IFERROR(XLOOKUP($G25&"."&$H25,CaseSource!$A$2:$A$371,CaseSource!$B$2:$B$371,""),"")
A26: city | B26: Pre-File | C26: Loan Sticky Header | D26: Always | F26: 2 | G26: CPV_DETAIL.json | H26: RESI_CITY | I26: identity | J26: Y | K26: clean | L26: =IFERROR(XLOOKUP($G26&"."&$H26,CaseSource!$A$2:$A$371,CaseSource!$B$2:$B$371,""),"")
A27: co_aadhaar | B27: Pre-File | C27: Co Applicant Section | D27: Always | F27: 1 | G27: AUTH_SIGNATORY.json | H27: AUTH_AADHAAR_NUMBER | I27: identity | J27: Y | K27: clean | L27: =IFERROR(XLOOKUP($G27&"."&$H27,CaseSource!$A$2:$A$371,CaseSource!$B$2:$B$371,""),"")
A28: co_aadhaar | B28: Pre-File | C28: Co Applicant Section | D28: Always | F28: 2 | G28: GURANTOR.json | H28: G_AADHAAR_NUMBER | I28: identity | J28: Y | K28: clean | L28: =IFERROR(XLOOKUP($G28&"."&$H28,CaseSource!$A$2:$A$371,CaseSource!$B$2:$B$371,""),"")
A29: co_aadhaar | B29: Pre-File | C29: Co Applicant Section | D29: Always | F29: 3 | G29: CPV_DETAIL.json | H29: AADHAAR_NUMBER | I29: identity | J29: Y | K29: clean | L29: =IFERROR(XLOOKUP($G29&"."&$H29,CaseSource!$A$2:$A$371,CaseSource!$B$2:$B$371,""),"")
A30: co_address | B30: Pre-File | C30: Co Applicant Section | D30: Always | F30: 1 | G30: AUTH_SIGNATORY.json | H30: ADD1_1 | I30: identity | J30: Y | K30: clean | L30: =IFERROR(XLOOKUP($G30&"."&$H30,CaseSource!$A$2:$A$371,CaseSource!$B$2:$B$371,""),"")
... A36: co_city | B36: Pre-File | C36: Co Applicant Section | D36: Always | F36: 3 | G36: CPV_DETAIL.json | H36: RESI_CITY | I36: identity | J36: Y | K36: clean | L36: =IFERROR(XLOOKUP($G36&"."&$H36,CaseSource!$A$2:$A$371,CaseSource!$B$2:$B$371,""),"")
A37: co_currentExperience` / `co_totalExperience | D37: Always | F37: 1 | G37: CPV_DETAIL.json | H37: YEAR_AT_PROFESSION | I37: identity | J37: Y | K37: numeric | L37: =IFERROR(XLOOKUP($G37&"."&$H37,CaseSource!$A$2:$A$371,CaseSource!$B$2:$B$371,""),"")
A38: co_customerName | B38: Pre-File | C38: Co Applicant Section | D38: Always | F38: 1 | G38: AUTH_SIGNATORY.json | H38: NAME_1 | I38: identity | J38: Y | K38: clean | L38: =IFERROR(XLOOKUP($G38&"."&$H38,CaseSource!$A$2:$A$371,CaseSource!$B$2:$B$371,""),"")
A39: co_customerName | B39: Pre-File | C39: Co Applicant Section | D39: Always | F39: 2 | G39: AUTH_SIGNATORY.json | H39: NAME | I39: identity | J39: Y | K39: clean | L39: =IFERROR(XLOOKUP($G39&"."&$H39,CaseSource!$A$2:$A$371,CaseSource!$B$2:$B$371,""),"")
A40: co_customerName | B40: Pre-File | C40: Co Applicant Section | D40: Always | F40: 3 | G40: GURANTOR.json | H40: NAME | I40: identity | J40: Y | K40: clean | L40: =IFERROR(XLOOKUP($G40&"."&$H40,CaseSource!$A$2:$A$371,CaseSource!$B$2:$B$371,""),"")
A41: co_dependents | B41: Pre-File | C41: Co Applicant Section | D41: Always | F41: 1 | G41: CPV_DETAIL.json | H41: NO_OF_DEPENDANTS | I41: identity | J41: Y | K41: numeric | L41: =IFERROR(XLOOKUP($G41&"."&$H41,CaseSource!$A$2:$A$371,CaseSource!$B$2:$B$371,""),"")
A42: co_dependents | B42: Pre-File | C42: Co Applicant Section | D42: Always | F42: 2 | G42: GURANTOR.json | H42: NO_OF_DEPEND | I42: identity | J42: Y | K42: numeric | L42: =IFERROR(XLOOKUP($G42&"."&$H42,CaseSource!$A$2:$A$371,CaseSource!$B$2:$B$371,""),"")
A43: co_designation | B43: Pre-File | C43: Co Applicant Section | D43: Always | F43: 1 | G43: AUTH_SIGNATORY.json | H43: DESIGNATION_1 | I43: identity | J43: Y | K43: clean | L43: =IFERROR(XLOOKUP($G43&"."&$H43,CaseSource!$A$2:$A$371,CaseSource!$B$2:$B$371,""),"")
A44: co_dob | B44: Pre-File | C44: Co Applicant Section | D44: Always | F44: 1 | G44: AUTH_SIGNATORY.json | H44: DATE_OF_BIRTH_1 | I44: identity | J44: Y | K44: ISO | L44: =IFERROR(XLOOKUP($G44&"."&$H44,CaseSource!$A$2:$A$371,CaseSource!$B$2:$B$371,""),"")
A45: co_dob | B45: Pre-File | C45: Co Applicant Section | D45: Always | F45: 2 | G45: CPV_DETAIL.json | H45: DATE_OF_BIRTH | I45: identity | J45: Y | K45: ISO | L45: =IFERROR(XLOOKUP($G45&"."&$H45,CaseSource!$A$2:$A$371,CaseSource!$B$2:$B$371,""),"")
...

Sheet CaseSource
A1: source_path | B1: value
A2: AUTH_SIGNATORY.json.ACCOUNT_NUMBER_TYPE | B2: CPV
A3: AUTH_SIGNATORY.json.ADD1 | B3: C-5 1504 CLEO COUNTY NOIDA SECTOR-121
A4: AUTH_SIGNATORY.json.ADD2
A5: AUTH_SIGNATORY.json.AUTH_AADHAAR_NUMBER | B5: 951419463882
A6: AUTH_SIGNATORY.json.CITY | B6: NOIDA
A7: AUTH_SIGNATORY.json.CPV_ACCOUNT_NO | B7: 3419
A8: AUTH_SIGNATORY.json.DATA_LOCATION_CODE | B8: 03
A9: AUTH_SIGNATORY.json.DATE_OF_BIRTH | B9: 1987-09-09T00:00:00
A10: AUTH_SIGNATORY.json.DESIGNATION | B10: DIRECTOR
A11: AUTH_SIGNATORY.json.FAX
A12: AUTH_SIGNATORY.json.HP_GROUP | B12: 01
A13: AUTH_SIGNATORY.json.MOBILE
A14: AUTH_SIGNATORY.json.NAME | B14: GAURAV KHANNA
A15: AUTH_SIGNATORY.json.ORIGINAL_HP_GROUP
A16: AUTH_SIGNATORY.json.PHONE | B16: 9811542232
A17: AUTH_SIGNATORY.json.PIN | B17: 201309
A18: CPV_DETAIL.json.AADHAAR_NUMBER
A19: CPV_DETAIL.json.ACCOUNT_NUMBER_TYPE | B19: CPV
A20: CPV_DETAIL.json.ANNUAL_INCOME | B20: 3797080
A21: CPV_DETAIL.json.CAR_MODEL | B21: S PRESSO LXI CNG
A22: CPV_DETAIL.json.CATEGORY | B22: PVT LTD
A23: CPV_DETAIL.json.CDB_ACCOUNT_NO | B23: 3000004231
A24: CPV_DETAIL.json.CLS_REMARKS
A25: CPV_DETAIL.json.CLS_STATUS
A26: CPV_DETAIL.json.CPV_ACCOUNT_NO | B26: 3419
A27: CPV_DETAIL.json.CPV_DATE | B27: 2025-01-02T00:00:00
A28: CPV_DETAIL.json.CPV_G_OFF_STATUS
A29: CPV_DETAIL.json.CPV_G_RES_STATUS
A30: CPV_DETAIL.json.CPV_MONTH_YEAR | B30: 012025
A31: CPV_DETAIL.json.CPV_OFF_STATUS
A32: CPV_DETAIL.json.CPV_RES_STATUS
A33: CPV_DETAIL.json.CPV_SEND_AT_TIME
A34: CPV_DETAIL.json.CPV_SEND_ON_DATE
A35: CPV_DETAIL.json.CREATED_BY_USER
A36: CPV_DETAIL.json.CREATED_ON_DATE
A37: CPV_DETAIL.json.CREATED_ON_TIME
A38: CPV_DETAIL.json.CUST_NAME_FIRST | B38: GOURAV
A39: CPV_DETAIL.json.CUST_NAME_LAST | B39: PVT LTD 2
A40: CPV_DETAIL.json.CUST_NAME_MIDDLE | B40: LUMINARIES
...
