Workbook
Name NewFieldOptionsDisplay: 'DropdownData'!$A$2:$A$327
Name RoleFirst: 'DropdownData'!$C$2:$C$22
Name RoleNext: 'DropdownData'!$D$2:$D$21

Sheet LegacyToNewMap
A1: legacy_file | B1: legacy_field | C1: legacy_value | D1: new_field_select | E1: mapping_role | F1: comments_normalization | G1: new_field_dropdown_values | H1: new_field_key
A2: AUTH_SIGNATORY.json | B2: ACCOUNT_NUMBER_TYPE | C2: CPV | G2: =IFERROR(XLOOKUP($D2,NewFieldOptions!$A:$A,NewFieldOptions!$D:$D,""),"") | H2: =IFERROR(XLOOKUP($D2,NewFieldOptions!$A:$A,NewFieldOptions!$B:$B,""),"")
A3: AUTH_SIGNATORY.json | B3: ADD1 | C3: C-5 1504 CLEO COUNTY NOIDA SECTOR-121 | G3: =IFERROR(XLOOKUP($D3,NewFieldOptions!$A:$A,NewFieldOptions!$D:$D,""),"") | H3: =IFERROR(XLOOKUP($D3,NewFieldOptions!$A:$A,NewFieldOptions!$B:$B,""),"")
A4: AUTH_SIGNATORY.json | B4: ADD2 | G4: =IFERROR(XLOOKUP($D4,NewFieldOptions!$A:$A,NewFieldOptions!$D:$D,""),"") | H4: =IFERROR(XLOOKUP($D4,NewFieldOptions!$A:$A,NewFieldOptions!$B:$B,""),"")
A5: AUTH_SIGNATORY.json | B5: AUTH_AADHAAR_NUMBER | C5: 951419463882 | G5: =IFERROR(XLOOKUP($D5,NewFieldOptions!$A:$A,NewFieldOptions!$D:$D,""),"") | H5: =IFERROR(XLOOKUP($D5,NewFieldOptions!$A:$A,NewFieldOptions!$B:$B,""),"")
A6: AUTH_SIGNATORY.json | B6: CITY | C6: NOIDA | G6: =IFERROR(XLOOKUP($D6,NewFieldOptions!$A:$A,NewFieldOptions!$D:$D,""),"") | H6: =IFERROR(XLOOKUP($D6,NewFieldOptions!$A:$A,NewFieldOptions!$B:$B,""),"")
A7: AUTH_SIGNATORY.json | B7: CPV_ACCOUNT_NO | C7: 3419 | G7: =IFERROR(XLOOKUP($D7,NewFieldOptions!$A:$A,NewFieldOptions!$D:$D,""),"") | H7: =IFERROR(XLOOKUP($D7,NewFieldOptions!$A:$A,NewFieldOptions!$B:$B,""),"")
A8: AUTH_SIGNATORY.json | B8: DATA_LOCATION_CODE | C8: 03 | G8: =IFERROR(XLOOKUP($D8,NewFieldOptions!$A:$A,NewFieldOptions!$D:$D,""),"") | H8: =IFERROR(XLOOKUP($D8,NewFieldOptions!$A:$A,NewFieldOptions!$B:$B,""),"")
A9: AUTH_SIGNATORY.json | B9: DATE_OF_BIRTH | C9: 1987-09-09T00:00:00 | G9: =IFERROR(XLOOKUP($D9,NewFieldOptions!$A:$A,NewFieldOptions!$D:$D,""),"") | H9: =IFERROR(XLOOKUP($D9,NewFieldOptions!$A:$A,NewFieldOptions!$B:$B,""),"")
A10: AUTH_SIGNATORY.json | B10: DESIGNATION | C10: DIRECTOR | G10: =IFERROR(XLOOKUP($D10,NewFieldOptions!$A:$A,NewFieldOptions!$D:$D,""),"") | H10: =IFERROR(XLOOKUP($D10,NewFieldOptions!$A:$A,NewFieldOptions!$B:$B,""),"")
A11: AUTH_SIGNATORY.json | B11: FAX | G11: =IFERROR(XLOOKUP($D11,NewFieldOptions!$A:$A,NewFieldOptions!$D:$D,""),"") | H11: =IFERROR(XLOOKUP($D11,NewFieldOptions!$A:$A,NewFieldOptions!$B:$B,""),"")
A12: AUTH_SIGNATORY.json | B12: HP_GROUP | C12: 01 | G12: =IFERROR(XLOOKUP($D12,NewFieldOptions!$A:$A,NewFieldOptions!$D:$D,""),"") | H12: =IFERROR(XLOOKUP($D12,NewFieldOptions!$A:$A,NewFieldOptions!$B:$B,""),"")
A13: AUTH_SIGNATORY.json | B13: MOBILE | G13: =IFERROR(XLOOKUP($D13,NewFieldOptions!$A:$A,NewFieldOptions!$D:$D,""),"") | H13: =IFERROR(XLOOKUP($D13,NewFieldOptions!$A:$A,NewFieldOptions!$B:$B,""),"")
A14: AUTH_SIGNATORY.json | B14: NAME | C14: GAURAV KHANNA | G14: =IFERROR(XLOOKUP($D14,NewFieldOptions!$A:$A,NewFieldOptions!$D:$D,""),"") | H14: =IFERROR(XLOOKUP($D14,NewFieldOptions!$A:$A,NewFieldOptions!$B:$B,""),"")
A15: AUTH_SIGNATORY.json | B15: ORIGINAL_HP_GROUP | G15: =IFERROR(XLOOKUP($D15,NewFieldOptions!$A:$A,NewFieldOptions!$D:$D,""),"") | H15: =IFERROR(XLOOKUP($D15,NewFieldOptions!$A:$A,NewFieldOptions!$B:$B,""),"")
A16: AUTH_SIGNATORY.json | B16: PHONE | C16: 9811542232 | G16: =IFERROR(XLOOKUP($D16,NewFieldOptions!$A:$A,NewFieldOptions!$D:$D,""),"") | H16: =IFERROR(XLOOKUP($D16,NewFieldOptions!$A:$A,NewFieldOptions!$B:$B,""),"")
A17: AUTH_SIGNATORY.json | B17: PIN | C17: 201309 | G17: =IFERROR(XLOOKUP($D17,NewFieldOptions!$A:$A,NewFieldOptions!$D:$D,""),"") | H17: =IFERROR(XLOOKUP($D17,NewFieldOptions!$A:$A,NewFieldOptions!$B:$B,""),"")
A18: CPV_DETAIL.json | B18: AADHAAR_NUMBER | G18: =IFERROR(XLOOKUP($D18,NewFieldOptions!$A:$A,NewFieldOptions!$D:$D,""),"") | H18: =IFERROR(XLOOKUP($D18,NewFieldOptions!$A:$A,NewFieldOptions!$B:$B,""),"")
A19: CPV_DETAIL.json | B19: ACCOUNT_NUMBER_TYPE | C19: CPV | G19: =IFERROR(XLOOKUP($D19,NewFieldOptions!$A:$A,NewFieldOptions!$D:$D,""),"") | H19: =IFERROR(XLOOKUP($D19,NewFieldOptions!$A:$A,NewFieldOptions!$B:$B,""),"")
A20: CPV_DETAIL.json | B20: ANNUAL_INCOME | C20: 3797080 | G20: =IFERROR(XLOOKUP($D20,NewFieldOptions!$A:$A,NewFieldOptions!$D:$D,""),"") | H20: =IFERROR(XLOOKUP($D20,NewFieldOptions!$A:$A,NewFieldOptions!$B:$B,""),"")
A21: CPV_DETAIL.json | B21: CAR_MODEL | C21: S PRESSO LXI CNG | G21: =IFERROR(XLOOKUP($D21,NewFieldOptions!$A:$A,NewFieldOptions!$D:$D,""),"") | H21: =IFERROR(XLOOKUP($D21,NewFieldOptions!$A:$A,NewFieldOptions!$B:$B,""),"")
A22: CPV_DETAIL.json | B22: CATEGORY | C22: PVT LTD | G22: =IFERROR(XLOOKUP($D22,NewFieldOptions!$A:$A,NewFieldOptions!$D:$D,""),"") | H22: =IFERROR(XLOOKUP($D22,NewFieldOptions!$A:$A,NewFieldOptions!$B:$B,""),"")
A23: CPV_DETAIL.json | B23: CDB_ACCOUNT_NO | C23: 3000004231 | G23: =IFERROR(XLOOKUP($D23,NewFieldOptions!$A:$A,NewFieldOptions!$D:$D,""),"") | H23: =IFERROR(XLOOKUP($D23,NewFieldOptions!$A:$A,NewFieldOptions!$B:$B,""),"")
A24: CPV_DETAIL.json | B24: CLS_REMARKS | G24: =IFERROR(XLOOKUP($D24,NewFieldOptions!$A:$A,NewFieldOptions!$D:$D,""),"") | H24: =IFERROR(XLOOKUP($D24,NewFieldOptions!$A:$A,NewFieldOptions!$B:$B,""),"")
A25: CPV_DETAIL.json | B25: CLS_STATUS | G25: =IFERROR(XLOOKUP($D25,NewFieldOptions!$A:$A,NewFieldOptions!$D:$D,""),"") | H25: =IFERROR(XLOOKUP($D25,NewFieldOptions!$A:$A,NewFieldOptions!$B:$B,""),"")
A26: CPV_DETAIL.json | B26: CPV_ACCOUNT_NO | C26: 3419 | G26: =IFERROR(XLOOKUP($D26,NewFieldOptions!$A:$A,NewFieldOptions!$D:$D,""),"") | H26: =IFERROR(XLOOKUP($D26,NewFieldOptions!$A:$A,NewFieldOptions!$B:$B,""),"")
A27: CPV_DETAIL.json | B27: CPV_DATE | C27: 2025-01-02T00:00:00 | G27: =IFERROR(XLOOKUP($D27,NewFieldOptions!$A:$A,NewFieldOptions!$D:$D,""),"") | H27: =IFERROR(XLOOKUP($D27,NewFieldOptions!$A:$A,NewFieldOptions!$B:$B,""),"")
A28: CPV_DETAIL.json | B28: CPV_G_OFF_STATUS | G28: =IFERROR(XLOOKUP($D28,NewFieldOptions!$A:$A,NewFieldOptions!$D:$D,""),"") | H28: =IFERROR(XLOOKUP($D28,NewFieldOptions!$A:$A,NewFieldOptions!$B:$B,""),"")
A29: CPV_DETAIL.json | B29: CPV_G_RES_STATUS | G29: =IFERROR(XLOOKUP($D29,NewFieldOptions!$A:$A,NewFieldOptions!$D:$D,""),"") | H29: =IFERROR(XLOOKUP($D29,NewFieldOptions!$A:$A,NewFieldOptions!$B:$B,""),"")
A30: CPV_DETAIL.json | B30: CPV_MONTH_YEAR | C30: 012025 | G30: =IFERROR(XLOOKUP($D30,NewFieldOptions!$A:$A,NewFieldOptions!$D:$D,""),"") | H30: =IFERROR(XLOOKUP($D30,NewFieldOptions!$A:$A,NewFieldOptions!$B:$B,""),"")
A31: CPV_DETAIL.json | B31: CPV_OFF_STATUS | G31: =IFERROR(XLOOKUP($D31,NewFieldOptions!$A:$A,NewFieldOptions!$D:$D,""),"") | H31: =IFERROR(XLOOKUP($D31,NewFieldOptions!$A:$A,NewFieldOptions!$B:$B,""),"")
A32: CPV_DETAIL.json | B32: CPV_RES_STATUS | G32: =IFERROR(XLOOKUP($D32,NewFieldOptions!$A:$A,NewFieldOptions!$D:$D,""),"") | H32: =IFERROR(XLOOKUP($D32,NewFieldOptions!$A:$A,NewFieldOptions!$B:$B,""),"")
A33: CPV_DETAIL.json | B33: CPV_SEND_AT_TIME | G33: =IFERROR(XLOOKUP($D33,NewFieldOptions!$A:$A,NewFieldOptions!$D:$D,""),"") | H33: =IFERROR(XLOOKUP($D33,NewFieldOptions!$A:$A,NewFieldOptions!$B:$B,""),"")
A34: CPV_DETAIL.json | B34: CPV_SEND_ON_DATE | G34: =IFERROR(XLOOKUP($D34,NewFieldOptions!$A:$A,NewFieldOptions!$D:$D,""),"") | H34: =IFERROR(XLOOKUP($D34,NewFieldOptions!$A:$A,NewFieldOptions!$B:$B,""),"")
A35: CPV_DETAIL.json | B35: CREATED_BY_USER | G35: =IFERROR(XLOOKUP($D35,NewFieldOptions!$A:$A,NewFieldOptions!$D:$D,""),"") | H35: =IFERROR(XLOOKUP($D35,NewFieldOptions!$A:$A,NewFieldOptions!$B:$B,""),"")
A36: CPV_DETAIL.json | B36: CREATED_ON_DATE | G36: =IFERROR(XLOOKUP($D36,NewFieldOptions!$A:$A,NewFieldOptions!$D:$D,""),"") | H36: =IFERROR(XLOOKUP($D36,NewFieldOptions!$A:$A,NewFieldOptions!$B:$B,""),"")
A37: CPV_DETAIL.json | B37: CREATED_ON_TIME | G37: =IFERROR(XLOOKUP($D37,NewFieldOptions!$A:$A,NewFieldOptions!$D:$D,""),"") | H37: =IFERROR(XLOOKUP($D37,NewFieldOptions!$A:$A,NewFieldOptions!$B:$B,""),"")
A38: CPV_DETAIL.json | B38: CUST_NAME_FIRST | C38: GOURAV | G38: =IFERROR(XLOOKUP($D38,NewFieldOptions!$A:$A,NewFieldOptions!$D:$D,""),"") | H38: =IFERROR(XLOOKUP($D38,NewFieldOptions!$A:$A,NewFieldOptions!$B:$B,""),"")
A39: CPV_DETAIL.json | B39: CUST_NAME_LAST | C39: PVT LTD 2 | G39: =IFERROR(XLOOKUP($D39,NewFieldOptions!$A:$A,NewFieldOptions!$D:$D,""),"") | H39: =IFERROR(XLOOKUP($D39,NewFieldOptions!$A:$A,NewFieldOptions!$B:$B,""),"")
A40: CPV_DETAIL.json | B40: CUST_NAME_MIDDLE | C40: LUMINARIES | G40: =IFERROR(XLOOKUP($D40,NewFieldOptions!$A:$A,NewFieldOptions!$D:$D,""),"") | H40: =IFERROR(XLOOKUP($D40,NewFieldOptions!$A:$A,NewFieldOptions!$B:$B,""),"")
...

Sheet NewFieldOptions
A1: display | B1: new_field | C1: display_label | D1: dropdown_values | E1: new_type
A2: __deliveryInitialized (__deliveryInitialized) | B2: __deliveryInitialized | C2: __deliveryInitialized | E2: string
A3: __dispatchInitialized (__dispatchInitialized) | B3: __dispatchInitialized | C3: __dispatchInitialized | E3: string
A4: __postfileLocked (__postfileLocked) | B4: __postfileLocked | C4: __postfileLocked | E4: string
A5: aadhaarCardDocUrl (aadhaarCardDocUrl) | B5: aadhaarCardDocUrl | C5: aadhaarCardDocUrl | E5: string
A6: accessoriesAmount (Accessories Amount) | B6: accessoriesAmount | C6: Accessories Amount | E6: number
A7: accountNumber (Applicant Account Number) | B7: accountNumber | C7: Applicant Account Number | E7: number
A8: accountSinceYears (Account Since (Years)) | B8: accountSinceYears | C8: Account Since (Years) | E8: number
A9: accountType (Account Type) | B9: accountType | C9: Account Type | E9: string
A10: addressProofDocUrl (addressProofDocUrl) | B10: addressProofDocUrl | C10: addressProofDocUrl | E10: string
A11: addressProofNumber (Address Proof Number) | B11: addressProofNumber | C11: Address Proof Number | E11: boolean
A12: addressProofType (Address Proof (type)) | B12: addressProofType | C12: Address Proof (type) | E12: boolean
A13: addressType (Address Type) | B13: addressType | C13: Address Type | E13: number
... A107: delivery_rcFile (delivery_rcFile) | B107: delivery_rcFile | C107: delivery_rcFile | E107: string
A108: dependents (Dependents) | B108: dependents | C108: Dependents | D108: owned | rented | Undergraduate | Graduate | Postgraduate | Others | E108: number
A109: designation (Designation) | B109: designation | C109: Designation | E109: string
A110: disburseAmount (Disbursement Amount) | B110: disburseAmount | C110: Disbursement Amount | E110: number
A111: disbursedDate (Disbursement Date) | B111: disbursedDate | C111: Disbursement Date | E111: string
A112: disbursement_date (disbursement_date) | B112: disbursement_date | C112: disbursement_date | E112: string
A113: disbursement_status (disbursement_status) | B113: disbursement_status | C113: disbursement_status | E113: string
A114: disbursement_time (disbursement_time) | B114: disbursement_time | C114: disbursement_time | E114: string
A115: disbursementDate (disbursementDate) | B115: disbursementDate | C115: disbursementDate | E115: string
A116: disbursementStatus (disbursementStatus) | B116: disbursementStatus | C116: disbursementStatus | E116: string
A117: dispatch_date (dispatch_date) | B117: dispatch_date | C117: dispatch_date | E117: string
A118: dispatch_through (dispatch_through) | B118: dispatch_through | C118: dispatch_through | E118: string
A119: dispatch_time (dispatch_time) | B119: dispatch_time | C119: dispatch_time | E119: string
A120: dlDocUrl (dlDocUrl) | B120: dlDocUrl | C120: dlDocUrl | E120: string
A121: dob (isCompany ? "Date of Incorporation" : "Date of Birth" [Individual: Date of Birth | Company: Date of Incorporation]) | B121: dob | C121: isCompany ? "Date of Incorporation" : "Date of Birth" [Individual: Date of Birth | Company: Date of Incorporation] | D121: Male | Female | Married | E121: number
A122: docsPreparedBy (Docs Prepared By) | B122: docsPreparedBy | C122: Docs Prepared By | E122: string
A123: ecs_accountNumber (ecs_accountNumber) | B123: ecs_accountNumber | C123: ecs_accountNumber | E123: number
A124: ecs_amount (ecs_amount) | B124: ecs_amount | C124: ecs_amount | E124: number
A125: ecs_bankName (ecs_bankName) | B125: ecs_bankName | C125: ecs_bankName | E125: number
A126: ecs_date (ecs_date) | B126: ecs_date | C126: ecs_date | E126: number
A127: ecs_favouring (ecs_favouring) | B127: ecs_favouring | C127: ecs_favouring | E127: string
A128: ecs_image (ecs_image) | B128: ecs_image | C128: ecs_image | E128: string
A129: ecs_micrCode (ecs_micrCode) | B129: ecs_micrCode | C129: ecs_micrCode | E129: number
A130: ecs_signedBy (ecs_signedBy) | B130: ecs_signedBy | C130: ecs_signedBy | E130: string
A131: ecs_tag (ecs_tag) | B131: ecs_tag | C131: ecs_tag | E131: string
A132: education (Education) | B132: education | C132: Education | D132: Undergraduate | Graduate | Postgraduate | Others | E132: string
A133: email (Email) | B133: email | C133: Email | E133: boolean
...

Sheet DropdownData
A1: new_field_display_options | C1: role_first | D1: role_next
A2: __deliveryInitialized (__deliveryInitialized) | C2: Mapping | D2: Fallback1
A3: __dispatchInitialized (__dispatchInitialized) | C3: Fallback1 | D3: Fallback2
A4: __postfileLocked (__postfileLocked) | C4: Fallback2 | D4: Fallback3
A5: aadhaarCardDocUrl (aadhaarCardDocUrl) | C5: Fallback3 | D5: Fallback4
A6: accessoriesAmount (Accessories Amount) | C6: Fallback4 | D6: Fallback5
A7: accountNumber (Applicant Account Number) | C7: Fallback5 | D7: Fallback6
A8: accountSinceYears (Account Since (Years)) | C8: Fallback6 | D8: Fallback7
A9: accountType (Account Type) | C9: Fallback7 | D9: Fallback8
A10: addressProofDocUrl (addressProofDocUrl) | C10: Fallback8 | D10: Fallback9
A11: addressProofNumber (Address Proof Number) | C11: Fallback9 | D11: Fallback10
A12: addressProofType (Address Proof (type)) | C12: Fallback10 | D12: Fallback11
... A21: approval_breakup_insuranceFinance (approval_breakup_insuranceFinance) | C21: Fallback19 | D21: Fallback20
A22: approval_breakup_netLoanApproved (approval_breakup_netLoanApproved) | C22: Fallback20
A23: approval_disbursedDate (approval_disbursedDate)
A24: approval_loanAmountApproved (approval_loanAmountApproved)
A25: approval_loanAmountDisbursed (approval_loanAmountDisbursed)
A26: approval_processingFees (approval_processingFees)
A27: approval_roi (approval_roi)
A28: approval_status (approval_status)
A29: approval_statusHistory (approval_statusHistory)
A30: approval_tenureMonths (approval_tenureMonths)
A31: bankName (Bank Name)
A32: billDate (billDate)
A33: billNumber (billNumber)
A34: boughtInYear (Bought In (Year))
... A327: yearsInCurrentHouse (Years in Current House)

Sheet UnmappedLegacyFields
A1: Unmapped legacy fields (new_field_select is blank)
A3: legacy_file | B3: legacy_field | C3: legacy_value | D3: new_field_select
A4: =IFERROR(FILTER(LegacyToNewMap!A:D,LegacyToNewMap!D:D=""),"All legacy fields mapped")

Sheet UnmappedNewFields
A1: Unmapped new software fields
A3: new_field_display | B3: new_field_key | C3: dropdown_values
A4: =IFERROR(FILTER(NewFieldOptions!A:C,COUNTIF(LegacyToNewMap!D:D,NewFieldOptions!A:A)=0),"All new fields mapped")

Sheet Instructions
A1: Reverse Mapping Instructions
A3: 1) Fill 'new_field_select' using dropdown in LegacyToNewMap.
A4: 2) Pick 'mapping_role' (Mapping/FallbackN).
A5: 3) Add comments and normalization notes in comments_normalization.
A6: 4) Use 'new_field_dropdown_values' to map legacy values to new dropdown values.
A7: 5) Same legacy field can map to multiple new fields (allowed).
A8: 6) First occurrence allows Mapping. Repeated occurrences allow only Fallback1..
A9: 7) Review UnmappedLegacyFields and UnmappedNewFields sheets after updates.
