Workbook
Name NewFieldOptionsDisplay: 'DropdownData'!$A$2:$A$500
Name RoleFirst: 'DropdownData'!$C$2:$C$22
Name RoleNext: 'DropdownData'!$D$2:$D$21

Sheet LegacyToNewMap
A1: legacy_file | B1: legacy_field | C1: legacy_value | D1: new_field_1 | E1: new_field_2 | F1: new_field_3 | G1: new_field_4 | H1: new_field_5 | I1: role_1 | J1: role_2 | K1: role_3 | L1: role_4 | M1: role_5 | N1: comments_normalization | O1: legacy_map_status
A2: AUTH_SIGNATORY.json | B2: ACCOUNT_NUMBER_TYPE | C2: CPV | O2: =IF(COUNTA(D2:H2)=0,"UNMAPPED","MAPPED")
A3: AUTH_SIGNATORY.json | B3: ADD1 | C3: C-5 1504 CLEO COUNTY NOIDA SECTOR-121 | O3: =IF(COUNTA(D3:H3)=0,"UNMAPPED","MAPPED")
A4: AUTH_SIGNATORY.json | B4: ADD2 | O4: =IF(COUNTA(D4:H4)=0,"UNMAPPED","MAPPED")
A5: AUTH_SIGNATORY.json | B5: AUTH_AADHAAR_NUMBER | C5: 951419463882 | D5: co_aadhaar (Aadhaar) | I5: Mapping | O5: =IF(COUNTA(D5:H5)=0,"UNMAPPED","MAPPED")
A6: AUTH_SIGNATORY.json | B6: CITY | C6: NOIDA | O6: =IF(COUNTA(D6:H6)=0,"UNMAPPED","MAPPED")
A7: AUTH_SIGNATORY.json | B7: CPV_ACCOUNT_NO | C7: 3419 | O7: =IF(COUNTA(D7:H7)=0,"UNMAPPED","MAPPED")
A8: AUTH_SIGNATORY.json | B8: DATA_LOCATION_CODE | C8: 03 | O8: =IF(COUNTA(D8:H8)=0,"UNMAPPED","MAPPED")
A9: AUTH_SIGNATORY.json | B9: DATE_OF_BIRTH | C9: 1987-09-09T00:00:00 | O9: =IF(COUNTA(D9:H9)=0,"UNMAPPED","MAPPED")
A10: AUTH_SIGNATORY.json | B10: DESIGNATION | C10: DIRECTOR | O10: =IF(COUNTA(D10:H10)=0,"UNMAPPED","MAPPED")
A11: AUTH_SIGNATORY.json | B11: FAX | O11: =IF(COUNTA(D11:H11)=0,"UNMAPPED","MAPPED")
A12: AUTH_SIGNATORY.json | B12: HP_GROUP | C12: 01 | O12: =IF(COUNTA(D12:H12)=0,"UNMAPPED","MAPPED")
A13: AUTH_SIGNATORY.json | B13: MOBILE | O13: =IF(COUNTA(D13:H13)=0,"UNMAPPED","MAPPED")
A14: AUTH_SIGNATORY.json | B14: NAME | C14: GAURAV KHANNA | D14: co_customerName (Name) | I14: Fallback1 | O14: =IF(COUNTA(D14:H14)=0,"UNMAPPED","MAPPED")
A15: AUTH_SIGNATORY.json | B15: ORIGINAL_HP_GROUP | O15: =IF(COUNTA(D15:H15)=0,"UNMAPPED","MAPPED")
A16: AUTH_SIGNATORY.json | B16: PHONE | C16: 9811542232 | D16: primaryMobile (Primary Mobile [Individual: Mobile | Company: Office Mobile]) | I16: Fallback3 | O16: =IF(COUNTA(D16:H16)=0,"UNMAPPED","MAPPED")
A17: AUTH_SIGNATORY.json | B17: PIN | C17: 201309 | O17: =IF(COUNTA(D17:H17)=0,"UNMAPPED","MAPPED")
A18: CPV_DETAIL.json | B18: AADHAAR_NUMBER | D18: addressProofNumber (Address Proof Number) | E18: co_aadhaar (Aadhaar) | F18: identityProofNumber (Identity Proof Number) | I18: Mapping | J18: Fallback2 | K18: Mapping | O18: =IF(COUNTA(D18:H18)=0,"UNMAPPED","MAPPED")
A19: CPV_DETAIL.json | B19: ACCOUNT_NUMBER_TYPE | C19: CPV | O19: =IF(COUNTA(D19:H19)=0,"UNMAPPED","MAPPED")
A20: CPV_DETAIL.json | B20: ANNUAL_INCOME | C20: 3797080 | D20: totalIncomeITR (Total Income (as per ITR)) | I20: Mapping | O20: =IF(COUNTA(D20:H20)=0,"UNMAPPED","MAPPED")
A21: CPV_DETAIL.json | B21: CAR_MODEL | C21: S PRESSO LXI CNG | D21: vehicleMake (Make) | I21: Fallback2 | O21: =IF(COUNTA(D21:H21)=0,"UNMAPPED","MAPPED")
A22: CPV_DETAIL.json | B22: CATEGORY | C22: PVT LTD | D22: companyType (Type of Company) | I22: Mapping | O22: =IF(COUNTA(D22:H22)=0,"UNMAPPED","MAPPED")
A23: CPV_DETAIL.json | B23: CDB_ACCOUNT_NO | C23: 3000004231 | O23: =IF(COUNTA(D23:H23)=0,"UNMAPPED","MAPPED")
A24: CPV_DETAIL.json | B24: CLS_REMARKS | O24: =IF(COUNTA(D24:H24)=0,"UNMAPPED","MAPPED")
A25: CPV_DETAIL.json | B25: CLS_STATUS | O25: =IF(COUNTA(D25:H25)=0,"UNMAPPED","MAPPED")
A26: CPV_DETAIL.json | B26: CPV_ACCOUNT_NO | C26: 3419 | O26: =IF(COUNTA(D26:H26)=0,"UNMAPPED","MAPPED")
A27: CPV_DETAIL.json | B27: CPV_DATE | C27: 2025-01-02T00:00:00 | D27: approval_approvalDate (approval_approvalDate) | E27: receivingDate (Receiving Date) | I27: Fallback3 | J27: Fallback2 | O27: =IF(COUNTA(D27:H27)=0,"UNMAPPED","MAPPED")
A28: CPV_DETAIL.json | B28: CPV_G_OFF_STATUS | O28: =IF(COUNTA(D28:H28)=0,"UNMAPPED","MAPPED")
A29: CPV_DETAIL.json | B29: CPV_G_RES_STATUS | O29: =IF(COUNTA(D29:H29)=0,"UNMAPPED","MAPPED")
A30: CPV_DETAIL.json | B30: CPV_MONTH_YEAR | C30: 012025 | O30: =IF(COUNTA(D30:H30)=0,"UNMAPPED","MAPPED")
A31: CPV_DETAIL.json | B31: CPV_OFF_STATUS | O31: =IF(COUNTA(D31:H31)=0,"UNMAPPED","MAPPED")
A32: CPV_DETAIL.json | B32: CPV_RES_STATUS | O32: =IF(COUNTA(D32:H32)=0,"UNMAPPED","MAPPED")
A33: CPV_DETAIL.json | B33: CPV_SEND_AT_TIME | O33: =IF(COUNTA(D33:H33)=0,"UNMAPPED","MAPPED")
A34: CPV_DETAIL.json | B34: CPV_SEND_ON_DATE | O34: =IF(COUNTA(D34:H34)=0,"UNMAPPED","MAPPED")
A35: CPV_DETAIL.json | B35: CREATED_BY_USER | O35: =IF(COUNTA(D35:H35)=0,"UNMAPPED","MAPPED")
A36: CPV_DETAIL.json | B36: CREATED_ON_DATE | O36: =IF(COUNTA(D36:H36)=0,"UNMAPPED","MAPPED")
A37: CPV_DETAIL.json | B37: CREATED_ON_TIME | O37: =IF(COUNTA(D37:H37)=0,"UNMAPPED","MAPPED")
A38: CPV_DETAIL.json | B38: CUST_NAME_FIRST | C38: GOURAV | O38: =IF(COUNTA(D38:H38)=0,"UNMAPPED","MAPPED")
A39: CPV_DETAIL.json | B39: CUST_NAME_LAST | C39: PVT LTD 2 | O39: =IF(COUNTA(D39:H39)=0,"UNMAPPED","MAPPED")
A40: CPV_DETAIL.json | B40: CUST_NAME_MIDDLE | C40: LUMINARIES | O40: =IF(COUNTA(D40:H40)=0,"UNMAPPED","MAPPED")
...

Sheet NewFieldOptions
A1: display | B1: new_field | C1: display_label | D1: dropdown_values | E1: new_type
A2: __deliveryInitialized (__deliveryInitialized) | B2: __deliveryInitialized | C2: __deliveryInitialized | E2: string
A3: __dispatchInitialized (__dispatchInitialized) | B3: __dispatchInitialized | C3: __dispatchInitialized | E3: string
A4: __postfileLocked (__postfileLocked) | B4: __postfileLocked | C4: __postfileLocked | E4: string
A5: aadhaarCardDocUrl (aadhaarCardDocUrl) | B5: aadhaarCardDocUrl | C5: aadhaarCardDocUrl | E5: string
A6: accessoriesAmount (Accessories Amount) | B6: accessoriesAmount | C6: Accessories Amount | E6: number
A7: accountNumber (Applicant Account Number) | B7: accountNumber | C7: Applicant Account Number | E7: number
A8: accountSinceYears (Account Since (Years)) | B8: accountSinceYears | C8: Account Since (Years) | E8: number
A9: accountType (Account Type) | B9: accountType | C9: Account Type | E9: string
A10: addressProofDocUrl (addressProofDocUrl) | B10: addressProofDocUrl | C10: addressProofDocUrl | E10: string
A11: addressProofNumber (Address Proof Number) | B11: addressProofNumber | C11: Address Proof Number | E11: boolean
A12: addressProofType (Address Proof (type)) | B12: addressProofType | C12: Address Proof (type) | E12: boolean
A13: addressType (Address Type) | B13: addressType | C13: Address Type | E13: number
... A279: delivery_rcFile (delivery_rcFile) | B279: delivery_rcFile | C279: delivery_rcFile | E279: string
A280: dependents (Dependents) | B280: dependents | C280: Dependents | D280: owned | rented | Undergraduate | Graduate | Postgraduate | Others | E280: number
A281: designation (Designation) | B281: designation | C281: Designation | E281: string
A282: disburseAmount (Disbursement Amount) | B282: disburseAmount | C282: Disbursement Amount | E282: number
A283: disbursedDate (Disbursement Date) | B283: disbursedDate | C283: Disbursement Date | E283: string
A284: disbursement_date (disbursement_date) | B284: disbursement_date | C284: disbursement_date | E284: string
A285: disbursement_status (disbursement_status) | B285: disbursement_status | C285: disbursement_status | E285: string
A286: disbursement_time (disbursement_time) | B286: disbursement_time | C286: disbursement_time | E286: string
A287: disbursementDate (disbursementDate) | B287: disbursementDate | C287: disbursementDate | E287: string
A288: disbursementStatus (disbursementStatus) | B288: disbursementStatus | C288: disbursementStatus | E288: string
A289: dispatch_date (dispatch_date) | B289: dispatch_date | C289: dispatch_date | E289: string
A290: dispatch_through (dispatch_through) | B290: dispatch_through | C290: dispatch_through | E290: string
A291: dispatch_time (dispatch_time) | B291: dispatch_time | C291: dispatch_time | E291: string
A292: dlDocUrl (dlDocUrl) | B292: dlDocUrl | C292: dlDocUrl | E292: string
A293: dob (isCompany ? "Date of Incorporation" : "Date of Birth" [Individual: Date of Birth | Company: Date of Incorporation]) | B293: dob | C293: isCompany ? "Date of Incorporation" : "Date of Birth" [Individual: Date of Birth | Company: Date of Incorporation] | D293: Male | Female | Married | E293: number
A294: docs_prepared_by (docs_prepared_by) | B294: docs_prepared_by | C294: docs_prepared_by | E294: string
A295: docsPreparedBy (Docs Prepared By) | B295: docsPreparedBy | C295: Docs Prepared By | E295: string
A296: ecs_accountNumber (ecs_accountNumber) | B296: ecs_accountNumber | C296: ecs_accountNumber | E296: number
A297: ecs_amount (ecs_amount) | B297: ecs_amount | C297: ecs_amount | E297: number
A298: ecs_bankName (ecs_bankName) | B298: ecs_bankName | C298: ecs_bankName | E298: number
A299: ecs_date (ecs_date) | B299: ecs_date | C299: ecs_date | E299: number
A300: ecs_favouring (ecs_favouring) | B300: ecs_favouring | C300: ecs_favouring | E300: string
A301: ecs_image (ecs_image) | B301: ecs_image | C301: ecs_image | E301: string
A302: ecs_micrCode (ecs_micrCode) | B302: ecs_micrCode | C302: ecs_micrCode | E302: number
A303: ecs_signedBy (ecs_signedBy) | B303: ecs_signedBy | C303: ecs_signedBy | E303: string
A304: ecs_tag (ecs_tag) | B304: ecs_tag | C304: ecs_tag | E304: string
A305: education (Education) | B305: education | C305: Education | D305: Undergraduate | Graduate | Postgraduate | Others | E305: string
...

Sheet DropdownData
A1: new_field_display_options | C1: role_first | D1: role_next
A2: __deliveryInitialized (__deliveryInitialized) | C2: Mapping | D2: Fallback1
A3: __dispatchInitialized (__dispatchInitialized) | C3: Fallback1 | D3: Fallback2
A4: __postfileLocked (__postfileLocked) | C4: Fallback2 | D4: Fallback3
A5: aadhaarCardDocUrl (aadhaarCardDocUrl) | C5: Fallback3 | D5: Fallback4
A6: accessoriesAmount (Accessories Amount) | C6: Fallback4 | D6: Fallback5
A7: accountNumber (Applicant Account Number) | C7: Fallback5 | D7: Fallback6
A8: accountSinceYears (Account Since (Years)) | C8: Fallback6 | D8: Fallback7
A9: accountType (Account Type) | C9: Fallback7 | D9: Fallback8
A10: addressProofDocUrl (addressProofDocUrl) | C10: Fallback8 | D10: Fallback9
A11: addressProofNumber (Address Proof Number) | C11: Fallback9 | D11: Fallback10
A12: addressProofType (Address Proof (type)) | C12: Fallback10 | D12: Fallback11
... A21: approval_breakup_insuranceFinance (approval_breakup_insuranceFinance) | C21: Fallback19 | D21: Fallback20
A22: approval_breakup_netLoanApproved (approval_breakup_netLoanApproved) | C22: Fallback20
A23: approval_disbursedDate (approval_disbursedDate)
A24: approval_loanAmountApproved (approval_loanAmountApproved)
A25: approval_loanAmountDisbursed (approval_loanAmountDisbursed)
A26: approval_processingFees (approval_processingFees)
A27: approval_roi (approval_roi)
A28: approval_status (approval_status)
A29: approval_statusHistory (approval_statusHistory)
A30: approval_tenureMonths (approval_tenureMonths)
A31: bankName (Bank Name)
A32: billDate (billDate)
A33: billNumber (billNumber)
A34: boughtInYear (Bought In (Year))
... A500: yearsInCurrentHouse (Years in Current House)

Sheet UnmappedLegacyFields
A1: Legacy field mapping status (filter legacy_map_status = UNMAPPED)
A2: legacy_file | B2: legacy_field | C2: legacy_value | D2: legacy_map_status
A3: AUTH_SIGNATORY.json | B3: ACCOUNT_NUMBER_TYPE | C3: CPV | D3: =LegacyToNewMap!O2
A4: AUTH_SIGNATORY.json | B4: ADD1 | C4: C-5 1504 CLEO COUNTY NOIDA SECTOR-121 | D4: =LegacyToNewMap!O3
A5: AUTH_SIGNATORY.json | B5: ADD2 | D5: =LegacyToNewMap!O4
A6: AUTH_SIGNATORY.json | B6: AUTH_AADHAAR_NUMBER | C6: 951419463882 | D6: =LegacyToNewMap!O5
A7: AUTH_SIGNATORY.json | B7: CITY | C7: NOIDA | D7: =LegacyToNewMap!O6
A8: AUTH_SIGNATORY.json | B8: CPV_ACCOUNT_NO | C8: 3419 | D8: =LegacyToNewMap!O7
A9: AUTH_SIGNATORY.json | B9: DATA_LOCATION_CODE | C9: 03 | D9: =LegacyToNewMap!O8
A10: AUTH_SIGNATORY.json | B10: DATE_OF_BIRTH | C10: 1987-09-09T00:00:00 | D10: =LegacyToNewMap!O9
A11: AUTH_SIGNATORY.json | B11: DESIGNATION | C11: DIRECTOR | D11: =LegacyToNewMap!O10
A12: AUTH_SIGNATORY.json | B12: FAX | D12: =LegacyToNewMap!O11
A13: AUTH_SIGNATORY.json | B13: HP_GROUP | C13: 01 | D13: =LegacyToNewMap!O12
A14: AUTH_SIGNATORY.json | B14: MOBILE | D14: =LegacyToNewMap!O13
A15: AUTH_SIGNATORY.json | B15: NAME | C15: GAURAV KHANNA | D15: =LegacyToNewMap!O14
A16: AUTH_SIGNATORY.json | B16: ORIGINAL_HP_GROUP | D16: =LegacyToNewMap!O15
A17: AUTH_SIGNATORY.json | B17: PHONE | C17: 9811542232 | D17: =LegacyToNewMap!O16
A18: AUTH_SIGNATORY.json | B18: PIN | C18: 201309 | D18: =LegacyToNewMap!O17
A19: CPV_DETAIL.json | B19: AADHAAR_NUMBER | D19: =LegacyToNewMap!O18
A20: CPV_DETAIL.json | B20: ACCOUNT_NUMBER_TYPE | C20: CPV | D20: =LegacyToNewMap!O19
A21: CPV_DETAIL.json | B21: ANNUAL_INCOME | C21: 3797080 | D21: =LegacyToNewMap!O20
A22: CPV_DETAIL.json | B22: CAR_MODEL | C22: S PRESSO LXI CNG | D22: =LegacyToNewMap!O21
A23: CPV_DETAIL.json | B23: CATEGORY | C23: PVT LTD | D23: =LegacyToNewMap!O22
A24: CPV_DETAIL.json | B24: CDB_ACCOUNT_NO | C24: 3000004231 | D24: =LegacyToNewMap!O23
A25: CPV_DETAIL.json | B25: CLS_REMARKS | D25: =LegacyToNewMap!O24
A26: CPV_DETAIL.json | B26: CLS_STATUS | D26: =LegacyToNewMap!O25
A27: CPV_DETAIL.json | B27: CPV_ACCOUNT_NO | C27: 3419 | D27: =LegacyToNewMap!O26
A28: CPV_DETAIL.json | B28: CPV_DATE | C28: 2025-01-02T00:00:00 | D28: =LegacyToNewMap!O27
A29: CPV_DETAIL.json | B29: CPV_G_OFF_STATUS | D29: =LegacyToNewMap!O28
A30: CPV_DETAIL.json | B30: CPV_G_RES_STATUS | D30: =LegacyToNewMap!O29
A31: CPV_DETAIL.json | B31: CPV_MONTH_YEAR | C31: 012025 | D31: =LegacyToNewMap!O30
A32: CPV_DETAIL.json | B32: CPV_OFF_STATUS | D32: =LegacyToNewMap!O31
A33: CPV_DETAIL.json | B33: CPV_RES_STATUS | D33: =LegacyToNewMap!O32
A34: CPV_DETAIL.json | B34: CPV_SEND_AT_TIME | D34: =LegacyToNewMap!O33
A35: CPV_DETAIL.json | B35: CPV_SEND_ON_DATE | D35: =LegacyToNewMap!O34
A36: CPV_DETAIL.json | B36: CREATED_BY_USER | D36: =LegacyToNewMap!O35
A37: CPV_DETAIL.json | B37: CREATED_ON_DATE | D37: =LegacyToNewMap!O36
A38: CPV_DETAIL.json | B38: CREATED_ON_TIME | D38: =LegacyToNewMap!O37
A39: CPV_DETAIL.json | B39: CUST_NAME_FIRST | C39: GOURAV | D39: =LegacyToNewMap!O38
A40: CPV_DETAIL.json | B40: CUST_NAME_LAST | C40: PVT LTD 2 | D40: =LegacyToNewMap!O39
...

Sheet UnmappedNewFields
A1: New field mapping status (filter mapped_count = 0)
A2: new_field_display | B2: new_field_key | C2: dropdown_values | D2: mapped_count
A3: __deliveryInitialized (__deliveryInitialized) | B3: __deliveryInitialized | D3: =COUNTIF(LegacyToNewMap!$D:$H,A3)
A4: __dispatchInitialized (__dispatchInitialized) | B4: __dispatchInitialized | D4: =COUNTIF(LegacyToNewMap!$D:$H,A4)
A5: __postfileLocked (__postfileLocked) | B5: __postfileLocked | D5: =COUNTIF(LegacyToNewMap!$D:$H,A5)
A6: aadhaarCardDocUrl (aadhaarCardDocUrl) | B6: aadhaarCardDocUrl | D6: =COUNTIF(LegacyToNewMap!$D:$H,A6)
A7: accessoriesAmount (Accessories Amount) | B7: accessoriesAmount | D7: =COUNTIF(LegacyToNewMap!$D:$H,A7)
A8: accountNumber (Applicant Account Number) | B8: accountNumber | D8: =COUNTIF(LegacyToNewMap!$D:$H,A8)
A9: accountSinceYears (Account Since (Years)) | B9: accountSinceYears | D9: =COUNTIF(LegacyToNewMap!$D:$H,A9)
A10: accountType (Account Type) | B10: accountType | D10: =COUNTIF(LegacyToNewMap!$D:$H,A10)
A11: addressProofDocUrl (addressProofDocUrl) | B11: addressProofDocUrl | D11: =COUNTIF(LegacyToNewMap!$D:$H,A11)
A12: addressProofNumber (Address Proof Number) | B12: addressProofNumber | D12: =COUNTIF(LegacyToNewMap!$D:$H,A12)
A13: addressProofType (Address Proof (type)) | B13: addressProofType | D13: =COUNTIF(LegacyToNewMap!$D:$H,A13)
A14: addressType (Address Type) | B14: addressType | D14: =COUNTIF(LegacyToNewMap!$D:$H,A14)
... A280: delivery_rcFile (delivery_rcFile) | B280: delivery_rcFile | D280: =COUNTIF(LegacyToNewMap!$D:$H,A280)
A281: dependents (Dependents) | B281: dependents | C281: owned | rented | Undergraduate | Graduate | Postgraduate | Others | D281: =COUNTIF(LegacyToNewMap!$D:$H,A281)
A282: designation (Designation) | B282: designation | D282: =COUNTIF(LegacyToNewMap!$D:$H,A282)
A283: disburseAmount (Disbursement Amount) | B283: disburseAmount | D283: =COUNTIF(LegacyToNewMap!$D:$H,A283)
A284: disbursedDate (Disbursement Date) | B284: disbursedDate | D284: =COUNTIF(LegacyToNewMap!$D:$H,A284)
A285: disbursement_date (disbursement_date) | B285: disbursement_date | D285: =COUNTIF(LegacyToNewMap!$D:$H,A285)
A286: disbursement_status (disbursement_status) | B286: disbursement_status | D286: =COUNTIF(LegacyToNewMap!$D:$H,A286)
A287: disbursement_time (disbursement_time) | B287: disbursement_time | D287: =COUNTIF(LegacyToNewMap!$D:$H,A287)
A288: disbursementDate (disbursementDate) | B288: disbursementDate | D288: =COUNTIF(LegacyToNewMap!$D:$H,A288)
A289: disbursementStatus (disbursementStatus) | B289: disbursementStatus | D289: =COUNTIF(LegacyToNewMap!$D:$H,A289)
A290: dispatch_date (dispatch_date) | B290: dispatch_date | D290: =COUNTIF(LegacyToNewMap!$D:$H,A290)
A291: dispatch_through (dispatch_through) | B291: dispatch_through | D291: =COUNTIF(LegacyToNewMap!$D:$H,A291)
A292: dispatch_time (dispatch_time) | B292: dispatch_time | D292: =COUNTIF(LegacyToNewMap!$D:$H,A292)
A293: dlDocUrl (dlDocUrl) | B293: dlDocUrl | D293: =COUNTIF(LegacyToNewMap!$D:$H,A293)
A294: dob (isCompany ? "Date of Incorporation" : "Date of Birth" [Individual: Date of Birth | Company: Date of Incorporation]) | B294: dob | C294: Male | Female | Married | D294: =COUNTIF(LegacyToNewMap!$D:$H,A294)
A295: docs_prepared_by (docs_prepared_by) | B295: docs_prepared_by | D295: =COUNTIF(LegacyToNewMap!$D:$H,A295)
A296: docsPreparedBy (Docs Prepared By) | B296: docsPreparedBy | D296: =COUNTIF(LegacyToNewMap!$D:$H,A296)
A297: ecs_accountNumber (ecs_accountNumber) | B297: ecs_accountNumber | D297: =COUNTIF(LegacyToNewMap!$D:$H,A297)
A298: ecs_amount (ecs_amount) | B298: ecs_amount | D298: =COUNTIF(LegacyToNewMap!$D:$H,A298)
A299: ecs_bankName (ecs_bankName) | B299: ecs_bankName | D299: =COUNTIF(LegacyToNewMap!$D:$H,A299)
A300: ecs_date (ecs_date) | B300: ecs_date | D300: =COUNTIF(LegacyToNewMap!$D:$H,A300)
A301: ecs_favouring (ecs_favouring) | B301: ecs_favouring | D301: =COUNTIF(LegacyToNewMap!$D:$H,A301)
A302: ecs_image (ecs_image) | B302: ecs_image | D302: =COUNTIF(LegacyToNewMap!$D:$H,A302)
A303: ecs_micrCode (ecs_micrCode) | B303: ecs_micrCode | D303: =COUNTIF(LegacyToNewMap!$D:$H,A303)
A304: ecs_signedBy (ecs_signedBy) | B304: ecs_signedBy | D304: =COUNTIF(LegacyToNewMap!$D:$H,A304)
A305: ecs_tag (ecs_tag) | B305: ecs_tag | D305: =COUNTIF(LegacyToNewMap!$D:$H,A305)
...

Sheet Instructions
A1: Reverse Mapping Instructions
A3: 1) Map each legacy field to one or more new fields via new_field_1..new_field_5.
A4: 2) Use role_1..role_5 as Mapping/Fallback1/Fallback2 as needed.
A5: 3) Same legacy field can map to multiple new fields in the same row.
A6: 4) Add normalization rules in comments_normalization (for dropdown conversion etc.).
A7: 5) In UnmappedLegacyFields sheet, filter legacy_map_status = UNMAPPED.
A8: 6) In UnmappedNewFields sheet, filter mapped_count = 0.
A9: 7) No dynamic Excel-only functions are used; workbook is compatibility-safe.
